File: Data/XRD/20231019-pin-c.csv
[Measurement conditions]
Sample identification,20231019-pin-c
Comment,
Anode material,Cu
K-Alpha1 wavelength,1.5405980
K-Alpha2 wavelength,1.5444260
Ratio K-Alpha2/K-Alpha1,0.500
Divergence slit,Fixed,0.10mm
Monochromator used,NO
Generator voltage, 40
Tube current, 15
File date and time,19/10ÔÂ/2023 21:21
Unit cell,
h k l, 0 0 0
Scan axis,Gonio
Scan range,3.016000000,59.956145600
Scan step size,0.0434658
No. of points, 1310
Scan type,CONTINUOUS
Time per step,56.865
[Scan points]
Angle, TimePerStep, Intensity, ESD
3.037732880, 56.865, 4489.0, 67.0000
3.081198640, 56.865, 4093.0, 63.9766
3.124664400, 56.865, 3792.0, 61.5792
3.168130160, 56.865, 3592.0, 59.9333
3.211595920, 56.865, 3469.0, 58.8982
3.255061680, 56.865, 3195.0, 56.5243
3.298527440, 56.865, 2875.0, 53.6190
3.341993200, 56.865, 2867.0, 53.5444
3.385458960, 56.865, 2806.0, 52.9717
3.428924720, 56.865, 2782.0, 52.7447
3.472390480, 56.865, 2531.0, 50.3090
3.515856240, 56.865, 2429.0, 49.2849
3.559322000, 56.865, 2432.0, 49.3153
3.602787760, 56.865, 2350.0, 48.4768
3.646253520, 56.865, 2286.0, 47.8121
3.689719280, 56.865, 2160.0, 46.4758
3.733185040, 56.865, 2153.0, 46.4004
3.776650800, 56.865, 2120.0, 46.0435
3.820116560, 56.865, 2061.0, 45.3982
3.863582320, 56.865, 1918.0, 43.7950
3.907048080, 56.865, 1921.0, 43.8292
3.950513840, 56.865, 1819.0, 42.6497
3.993979600, 56.865, 1800.0, 42.4264
4.037445360, 56.865, 1767.0, 42.0357
4.080911120, 56.865, 1623.0, 40.2865
4.124376880, 56.865, 1591.0, 39.8873
4.167842640, 56.865, 1594.0, 39.9249
4.211308400, 56.865, 1567.0, 39.5854
4.254774160, 56.865, 1574.0, 39.6737
4.298239920, 56.865, 1510.0, 38.8587
4.341705680, 56.865, 1326.0, 36.4143
4.385171440, 56.865, 1329.0, 36.4555
4.428637200, 56.865, 1338.0, 36.5787
4.472102960, 56.865, 1263.0, 35.5387
4.515568720, 56.865, 1272.0, 35.6651
4.559034480, 56.865, 1185.0, 34.4238
4.602500240, 56.865, 1226.0, 35.0143
4.645966000, 56.865, 1201.0, 34.6554
4.689431760, 56.865, 1084.0, 32.9242
4.732897520, 56.865, 1083.0, 32.9090
4.776363280, 56.865, 1053.0, 32.4500
4.819829040, 56.865, 997.0, 31.5753
4.863294800, 56.865, 1006.0, 31.7175
4.906760560, 56.865, 950.0, 30.8221
4.950226320, 56.865, 943.0, 30.7083
4.993692080, 56.865, 959.0, 30.9677
5.037157840, 56.865, 825.0, 28.7228
5.080623600, 56.865, 912.0, 30.1993
5.124089360, 56.865, 832.0, 28.8444
5.167555120, 56.865, 913.0, 30.2159
5.211020880, 56.865, 791.0, 28.1247
5.254486640, 56.865, 867.0, 29.4449
5.297952400, 56.865, 802.0, 28.3196
5.341418160, 56.865, 806.0, 28.3901
5.384883920, 56.865, 767.0, 27.6948
5.428349680, 56.865, 740.0, 27.2029
5.471815440, 56.865, 700.0, 26.4575
5.515281200, 56.865, 762.0, 27.6043
5.558746960, 56.865, 763.0, 27.6225
5.602212720, 56.865, 726.0, 26.9444
5.645678480, 56.865, 719.0, 26.8142
5.689144240, 56.865, 717.0, 26.7769
5.732610000, 56.865, 622.0, 24.9399
5.776075760, 56.865, 590.0, 24.2899
5.819541520, 56.865, 530.0, 23.0217
5.863007280, 56.865, 500.0, 22.3607
5.906473040, 56.865, 496.0, 22.2711
5.949938800, 56.865, 485.0, 22.0227
5.993404560, 56.865, 437.0, 20.9045
6.036870320, 56.865, 447.0, 21.1424
6.080336080, 56.865, 424.0, 20.5913
6.123801840, 56.865, 440.0, 20.9762
6.167267600, 56.865, 452.0, 21.2603
6.210733360, 56.865, 464.0, 21.5407
6.254199120, 56.865, 440.0, 20.9762
6.297664880, 56.865, 418.0, 20.4450
6.341130640, 56.865, 415.0, 20.3715
6.384596400, 56.865, 410.0, 20.2485
6.428062160, 56.865, 446.0, 21.1187
6.471527920, 56.865, 415.0, 20.3715
6.514993680, 56.865, 393.0, 19.8242
6.558459440, 56.865, 373.0, 19.3132
6.601925200, 56.865, 400.0, 20.0000
6.645390960, 56.865, 380.0, 19.4936
6.688856720, 56.865, 389.0, 19.7231
6.732322480, 56.865, 379.0, 19.4679
6.775788240, 56.865, 367.0, 19.1572
6.819254000, 56.865, 367.0, 19.1572
6.862719760, 56.865, 366.0, 19.1311
6.906185520, 56.865, 370.0, 19.2354
6.949651280, 56.865, 320.0, 17.8885
6.993117040, 56.865, 345.0, 18.5742
7.036582800, 56.865, 346.0, 18.6011
7.080048560, 56.865, 339.0, 18.4120
7.123514320, 56.865, 411.0, 20.2731
7.166980080, 56.865, 337.0, 18.3576
7.210445840, 56.865, 334.0, 18.2757
7.253911600, 56.865, 324.0, 18.0000
7.297377360, 56.865, 367.0, 19.1572
7.340843120, 56.865, 333.0, 18.2483
7.384308880, 56.865, 373.0, 19.3132
7.427774640, 56.865, 367.0, 19.1572
7.471240400, 56.865, 315.0, 17.7482
7.514706160, 56.865, 329.0, 18.1384
7.558171920, 56.865, 396.0, 19.8997
7.601637680, 56.865, 378.0, 19.4422
7.645103440, 56.865, 365.0, 19.1050
7.688569200, 56.865, 337.0, 18.3576
7.732034960, 56.865, 356.0, 18.8680
7.775500720, 56.865, 355.0, 18.8414
7.818966480, 56.865, 346.0, 18.6011
7.862432240, 56.865, 292.0, 17.0880
7.905898000, 56.865, 335.0, 18.3030
7.949363760, 56.865, 343.0, 18.5203
7.992829520, 56.865, 347.0, 18.6279
8.036295280, 56.865, 372.0, 19.2873
8.079761040, 56.865, 347.0, 18.6279
8.123226800, 56.865, 350.0, 18.7083
8.166692560, 56.865, 353.0, 18.7883
8.210158320, 56.865, 326.0, 18.0555
8.253624080, 56.865, 312.0, 17.6635
8.297089840, 56.865, 380.0, 19.4936
8.340555600, 56.865, 339.0, 18.4120
8.384021360, 56.865, 322.0, 17.9444
8.427487120, 56.865, 330.0, 18.1659
8.470952880, 56.865, 337.0, 18.3576
8.514418640, 56.865, 369.0, 19.2094
8.557884400, 56.865, 331.0, 18.1934
8.601350160, 56.865, 314.0, 17.7200
8.644815920, 56.865, 371.0, 19.2614
8.688281680, 56.865, 311.0, 17.6352
8.731747440, 56.865, 333.0, 18.2483
8.775213200, 56.865, 337.0, 18.3576
8.818678960, 56.865, 339.0, 18.4120
8.862144720, 56.865, 311.0, 17.6352
8.905610480, 56.865, 371.0, 19.2614
8.949076240, 56.865, 350.0, 18.7083
8.992542000, 56.865, 373.0, 19.3132
9.036007760, 56.865, 339.0, 18.4120
9.079473520, 56.865, 346.0, 18.6011
9.122939280, 56.865, 324.0, 18.0000
9.166405040, 56.865, 339.0, 18.4120
9.209870800, 56.865, 344.0, 18.5472
9.253336560, 56.865, 341.0, 18.4662
9.296802320, 56.865, 327.0, 18.0831
9.340268080, 56.865, 345.0, 18.5742
9.383733840, 56.865, 318.0, 17.8326
9.427199600, 56.865, 345.0, 18.5742
9.470665360, 56.865, 353.0, 18.7883
9.514131120, 56.865, 330.0, 18.1659
9.557596880, 56.865, 374.0, 19.3391
9.601062640, 56.865, 351.0, 18.7350
9.644528400, 56.865, 358.0, 18.9209
9.687994160, 56.865, 333.0, 18.2483
9.731459920, 56.865, 320.0, 17.8885
9.774925680, 56.865, 308.0, 17.5499
9.818391440, 56.865, 371.0, 19.2614
9.861857200, 56.865, 349.0, 18.6815
9.905322960, 56.865, 342.0, 18.4932
9.948788720, 56.865, 341.0, 18.4662
9.992254480, 56.865, 362.0, 19.0263
10.035720240, 56.865, 419.0, 20.4695
10.079186000, 56.865, 440.0, 20.9762
10.122651760, 56.865, 539.0, 23.2164
10.166117520, 56.865, 428.0, 20.6882
10.209583280, 56.865, 446.0, 21.1187
10.253049040, 56.865, 435.0, 20.8567
10.296514800, 56.865, 464.0, 21.5407
10.339980560, 56.865, 359.0, 18.9473
10.383446320, 56.865, 345.0, 18.5742
10.426912080, 56.865, 374.0, 19.3391
10.470377840, 56.865, 326.0, 18.0555
10.513843600, 56.865, 312.0, 17.6635
10.557309360, 56.865, 300.0, 17.3205
10.600775120, 56.865, 301.0, 17.3494
10.644240880, 56.865, 309.0, 17.5784
10.687706640, 56.865, 290.0, 17.0294
10.731172400, 56.865, 320.0, 17.8885
10.774638160, 56.865, 326.0, 18.0555
10.818103920, 56.865, 311.0, 17.6352
10.861569680, 56.865, 354.0, 18.8149
10.905035440, 56.865, 334.0, 18.2757
10.948501200, 56.865, 304.0, 17.4356
10.991966960, 56.865, 326.0, 18.0555
11.035432720, 56.865, 308.0, 17.5499
11.078898480, 56.865, 349.0, 18.6815
11.122364240, 56.865, 317.0, 17.8045
11.165830000, 56.865, 262.0, 16.1864
11.209295760, 56.865, 317.0, 17.8045
11.252761520, 56.865, 320.0, 17.8885
11.296227280, 56.865, 293.0, 17.1172
11.339693040, 56.865, 318.0, 17.8326
11.383158800, 56.865, 320.0, 17.8885
11.426624560, 56.865, 385.0, 19.6214
11.470090320, 56.865, 313.0, 17.6918
11.513556080, 56.865, 318.0, 17.8326
11.557021840, 56.865, 370.0, 19.2354
11.600487600, 56.865, 333.0, 18.2483
11.643953360, 56.865, 325.0, 18.0278
11.687419120, 56.865, 318.0, 17.8326
11.730884880, 56.865, 318.0, 17.8326
11.774350640, 56.865, 335.0, 18.3030
11.817816400, 56.865, 348.0, 18.6548
11.861282160, 56.865, 309.0, 17.5784
11.904747920, 56.865, 332.0, 18.2209
11.948213680, 56.865, 310.0, 17.6068
11.991679440, 56.865, 292.0, 17.0880
12.035145200, 56.865, 302.0, 17.3781
12.078610960, 56.865, 301.0, 17.3494
12.122076720, 56.865, 307.0, 17.5214
12.165542480, 56.865, 344.0, 18.5472
12.209008240, 56.865, 290.0, 17.0294
12.252474000, 56.865, 300.0, 17.3205
12.295939760, 56.865, 310.0, 17.6068
12.339405520, 56.865, 354.0, 18.8149
12.382871280, 56.865, 312.0, 17.6635
12.426337040, 56.865, 314.0, 17.7200
12.469802800, 56.865, 280.0, 16.7332
12.513268560, 56.865, 281.0, 16.7631
12.556734320, 56.865, 324.0, 18.0000
12.600200080, 56.865, 305.0, 17.4642
12.643665840, 56.865, 293.0, 17.1172
12.687131600, 56.865, 296.0, 17.2047
12.730597360, 56.865, 295.0, 17.1756
12.774063120, 56.865, 274.0, 16.5529
12.817528880, 56.865, 289.0, 17.0000
12.860994640, 56.865, 303.0, 17.4069
12.904460400, 56.865, 320.0, 17.8885
12.947926160, 56.865, 274.0, 16.5529
12.991391920, 56.865, 317.0, 17.8045
13.034857680, 56.865, 300.0, 17.3205
13.078323440, 56.865, 305.0, 17.4642
13.121789200, 56.865, 297.0, 17.2337
13.165254960, 56.865, 284.0, 16.8523
13.208720720, 56.865, 319.0, 17.8606
13.252186480, 56.865, 327.0, 18.0831
13.295652240, 56.865, 338.0, 18.3848
13.339118000, 56.865, 344.0, 18.5472
13.382583760, 56.865, 367.0, 19.1572
13.426049520, 56.865, 455.0, 21.3307
13.469515280, 56.865, 481.0, 21.9317
13.512981040, 56.865, 411.0, 20.2731
13.556446800, 56.865, 405.0, 20.1246
13.599912560, 56.865, 346.0, 18.6011
13.643378320, 56.865, 379.0, 19.4679
13.686844080, 56.865, 354.0, 18.8149
13.730309840, 56.865, 431.0, 20.7605
13.773775600, 56.865, 484.0, 22.0000
13.817241360, 56.865, 504.0, 22.4499
13.860707120, 56.865, 646.0, 25.4165
13.904172880, 56.865, 747.0, 27.3313
13.947638640, 56.865, 872.0, 29.5296
13.991104400, 56.865, 1112.0, 33.3467
14.034570160, 56.865, 1643.0, 40.5339
14.078035920, 56.865, 2534.0, 50.3389
14.121501680, 56.865, 3209.0, 56.6480
14.164967440, 56.865, 1984.0, 44.5421
14.208433200, 56.865, 817.0, 28.5832
14.251898960, 56.865, 481.0, 21.9317
14.295364720, 56.865, 415.0, 20.3715
14.338830480, 56.865, 399.0, 19.9750
14.382296240, 56.865, 351.0, 18.7350
14.425762000, 56.865, 331.0, 18.1934
14.469227760, 56.865, 359.0, 18.9473
14.512693520, 56.865, 341.0, 18.4662
14.556159280, 56.865, 293.0, 17.1172
14.599625040, 56.865, 309.0, 17.5784
14.643090800, 56.865, 318.0, 17.8326
14.686556560, 56.865, 336.0, 18.3303
14.730022320, 56.865, 267.0, 16.3401
14.773488080, 56.865, 325.0, 18.0278
14.816953840, 56.865, 334.0, 18.2757
14.860419600, 56.865, 326.0, 18.0555
14.903885360, 56.865, 300.0, 17.3205
14.947351120, 56.865, 295.0, 17.1756
14.990816880, 56.865, 287.0, 16.9411
15.034282640, 56.865, 281.0, 16.7631
15.077748400, 56.865, 328.0, 18.1108
15.121214160, 56.865, 299.0, 17.2916
15.164679920, 56.865, 281.0, 16.7631
15.208145680, 56.865, 317.0, 17.8045
15.251611440, 56.865, 311.0, 17.6352
15.295077200, 56.865, 283.0, 16.8226
15.338542960, 56.865, 289.0, 17.0000
15.382008720, 56.865, 291.0, 17.0587
15.425474480, 56.865, 333.0, 18.2483
15.468940240, 56.865, 314.0, 17.7200
15.512406000, 56.865, 310.0, 17.6068
15.555871760, 56.865, 324.0, 18.0000
15.599337520, 56.865, 283.0, 16.8226
15.642803280, 56.865, 300.0, 17.3205
15.686269040, 56.865, 278.0, 16.6733
15.729734800, 56.865, 305.0, 17.4642
15.773200560, 56.865, 269.0, 16.4012
15.816666320, 56.865, 296.0, 17.2047
15.860132080, 56.865, 288.0, 16.9706
15.903597840, 56.865, 287.0, 16.9411
15.947063600, 56.865, 285.0, 16.8819
15.990529360, 56.865, 305.0, 17.4642
16.033995120, 56.865, 302.0, 17.3781
16.077460880, 56.865, 292.0, 17.0880
16.120926640, 56.865, 277.0, 16.6433
16.164392400, 56.865, 284.0, 16.8523
16.207858160, 56.865, 255.0, 15.9687
16.251323920, 56.865, 282.0, 16.7929
16.294789680, 56.865, 307.0, 17.5214
16.338255440, 56.865, 269.0, 16.4012
16.381721200, 56.865, 300.0, 17.3205
16.425186960, 56.865, 312.0, 17.6635
16.468652720, 56.865, 265.0, 16.2788
16.512118480, 56.865, 300.0, 17.3205
16.555584240, 56.865, 293.0, 17.1172
16.599050000, 56.865, 261.0, 16.1555
16.642515760, 56.865, 287.0, 16.9411
16.685981520, 56.865, 279.0, 16.7033
16.729447280, 56.865, 285.0, 16.8819
16.772913040, 56.865, 338.0, 18.3848
16.816378800, 56.865, 289.0, 17.0000
16.859844560, 56.865, 322.0, 17.9444
16.903310320, 56.865, 325.0, 18.0278
16.946776080, 56.865, 307.0, 17.5214
16.990241840, 56.865, 309.0, 17.5784
17.033707600, 56.865, 286.0, 16.9115
17.077173360, 56.865, 298.0, 17.2627
17.120639120, 56.865, 295.0, 17.1756
17.164104880, 56.865, 261.0, 16.1555
17.207570640, 56.865, 298.0, 17.2627
17.251036400, 56.865, 344.0, 18.5472
17.294502160, 56.865, 314.0, 17.7200
17.337967920, 56.865, 295.0, 17.1756
17.381433680, 56.865, 324.0, 18.0000
17.424899440, 56.865, 334.0, 18.2757
17.468365200, 56.865, 315.0, 17.7482
17.511830960, 56.865, 315.0, 17.7482
17.555296720, 56.865, 305.0, 17.4642
17.598762480, 56.865, 290.0, 17.0294
17.642228240, 56.865, 309.0, 17.5784
17.685694000, 56.865, 300.0, 17.3205
17.729159760, 56.865, 287.0, 16.9411
17.772625520, 56.865, 286.0, 16.9115
17.816091280, 56.865, 301.0, 17.3494
17.859557040, 56.865, 309.0, 17.5784
17.903022800, 56.865, 306.0, 17.4929
17.946488560, 56.865, 282.0, 16.7929
17.989954320, 56.865, 297.0, 17.2337
18.033420080, 56.865, 288.0, 16.9706
18.076885840, 56.865, 321.0, 17.9165
18.120351600, 56.865, 324.0, 18.0000
18.163817360, 56.865, 272.0, 16.4924
18.207283120, 56.865, 284.0, 16.8523
18.250748880, 56.865, 298.0, 17.2627
18.294214640, 56.865, 282.0, 16.7929
18.337680400, 56.865, 326.0, 18.0555
18.381146160, 56.865, 310.0, 17.6068
18.424611920, 56.865, 294.0, 17.1464
18.468077680, 56.865, 294.0, 17.1464
18.511543440, 56.865, 291.0, 17.0587
18.555009200, 56.865, 288.0, 16.9706
18.598474960, 56.865, 261.0, 16.1555
18.641940720, 56.865, 317.0, 17.8045
18.685406480, 56.865, 315.0, 17.7482
18.728872240, 56.865, 302.0, 17.3781
18.772338000, 56.865, 276.0, 16.6132
18.815803760, 56.865, 300.0, 17.3205
18.859269520, 56.865, 300.0, 17.3205
18.902735280, 56.865, 279.0, 16.7033
18.946201040, 56.865, 310.0, 17.6068
18.989666800, 56.865, 298.0, 17.2627
19.033132560, 56.865, 288.0, 16.9706
19.076598320, 56.865, 312.0, 17.6635
19.120064080, 56.865, 322.0, 17.9444
19.163529840, 56.865, 289.0, 17.0000
19.206995600, 56.865, 291.0, 17.0587
19.250461360, 56.865, 313.0, 17.6918
19.293927120, 56.865, 312.0, 17.6635
19.337392880, 56.865, 345.0, 18.5742
19.380858640, 56.865, 333.0, 18.2483
19.424324400, 56.865, 307.0, 17.5214
19.467790160, 56.865, 325.0, 18.0278
19.511255920, 56.865, 318.0, 17.8326
19.554721680, 56.865, 351.0, 18.7350
19.598187440, 56.865, 324.0, 18.0000
19.641653200, 56.865, 342.0, 18.4932
19.685118960, 56.865, 344.0, 18.5472
19.728584720, 56.865, 335.0, 18.3030
19.772050480, 56.865, 417.0, 20.4206
19.815516240, 56.865, 469.0, 21.6564
19.858982000, 56.865, 605.0, 24.5967
19.902447760, 56.865, 689.0, 26.2488
19.945913520, 56.865, 1115.0, 33.3916
19.989379280, 56.865, 1700.0, 41.2311
20.032845040, 56.865, 1824.0, 42.7083
20.076310800, 56.865, 1137.0, 33.7194
20.119776560, 56.865, 574.0, 23.9583
20.163242320, 56.865, 423.0, 20.5670
20.206708080, 56.865, 382.0, 19.5448
20.250173840, 56.865, 349.0, 18.6815
20.293639600, 56.865, 375.0, 19.3649
20.337105360, 56.865, 345.0, 18.5742
20.380571120, 56.865, 365.0, 19.1050
20.424036880, 56.865, 341.0, 18.4662
20.467502640, 56.865, 335.0, 18.3030
20.510968400, 56.865, 318.0, 17.8326
20.554434160, 56.865, 349.0, 18.6815
20.597899920, 56.865, 371.0, 19.2614
20.641365680, 56.865, 359.0, 18.9473
20.684831440, 56.865, 328.0, 18.1108
20.728297200, 56.865, 370.0, 19.2354
20.771762960, 56.865, 304.0, 17.4356
20.815228720, 56.865, 319.0, 17.8606
20.858694480, 56.865, 356.0, 18.8680
20.902160240, 56.865, 309.0, 17.5784
20.945626000, 56.865, 325.0, 18.0278
20.989091760, 56.865, 364.0, 19.0788
21.032557520, 56.865, 340.0, 18.4391
21.076023280, 56.865, 344.0, 18.5472
21.119489040, 56.865, 353.0, 18.7883
21.162954800, 56.865, 357.0, 18.8944
21.206420560, 56.865, 361.0, 19.0000
21.249886320, 56.865, 400.0, 20.0000
21.293352080, 56.865, 352.0, 18.7617
21.336817840, 56.865, 409.0, 20.2237
21.380283600, 56.865, 388.0, 19.6977
21.423749360, 56.865, 360.0, 18.9737
21.467215120, 56.865, 396.0, 19.8997
21.510680880, 56.865, 387.0, 19.6723
21.554146640, 56.865, 399.0, 19.9750
21.597612400, 56.865, 350.0, 18.7083
21.641078160, 56.865, 341.0, 18.4662
21.684543920, 56.865, 340.0, 18.4391
21.728009680, 56.865, 347.0, 18.6279
21.771475440, 56.865, 356.0, 18.8680
21.814941200, 56.865, 357.0, 18.8944
21.858406960, 56.865, 313.0, 17.6918
21.901872720, 56.865, 341.0, 18.4662
21.945338480, 56.865, 342.0, 18.4932
21.988804240, 56.865, 370.0, 19.2354
22.032270000, 56.865, 340.0, 18.4391
22.075735760, 56.865, 358.0, 18.9209
22.119201520, 56.865, 368.0, 19.1833
22.162667280, 56.865, 365.0, 19.1050
22.206133040, 56.865, 339.0, 18.4120
22.249598800, 56.865, 355.0, 18.8414
22.293064560, 56.865, 366.0, 19.1311
22.336530320, 56.865, 387.0, 19.6723
22.379996080, 56.865, 367.0, 19.1572
22.423461840, 56.865, 390.0, 19.7484
22.466927600, 56.865, 358.0, 18.9209
22.510393360, 56.865, 378.0, 19.4422
22.553859120, 56.865, 380.0, 19.4936
22.597324880, 56.865, 365.0, 19.1050
22.640790640, 56.865, 385.0, 19.6214
22.684256400, 56.865, 330.0, 18.1659
22.727722160, 56.865, 338.0, 18.3848
22.771187920, 56.865, 379.0, 19.4679
22.814653680, 56.865, 386.0, 19.6469
22.858119440, 56.865, 370.0, 19.2354
22.901585200, 56.865, 381.0, 19.5192
22.945050960, 56.865, 315.0, 17.7482
22.988516720, 56.865, 339.0, 18.4120
23.031982480, 56.865, 377.0, 19.4165
23.075448240, 56.865, 369.0, 19.2094
23.118914000, 56.865, 369.0, 19.2094
23.162379760, 56.865, 406.0, 20.1494
23.205845520, 56.865, 387.0, 19.6723
23.249311280, 56.865, 468.0, 21.6333
23.292777040, 56.865, 500.0, 22.3607
23.336242800, 56.865, 537.0, 23.1733
23.379708560, 56.865, 451.0, 21.2368
23.423174320, 56.865, 339.0, 18.4120
23.466640080, 56.865, 415.0, 20.3715
23.510105840, 56.865, 399.0, 19.9750
23.553571600, 56.865, 360.0, 18.9737
23.597037360, 56.865, 382.0, 19.5448
23.640503120, 56.865, 364.0, 19.0788
23.683968880, 56.865, 356.0, 18.8680
23.727434640, 56.865, 390.0, 19.7484
23.770900400, 56.865, 349.0, 18.6815
23.814366160, 56.865, 345.0, 18.5742
23.857831920, 56.865, 386.0, 19.6469
23.901297680, 56.865, 414.0, 20.3470
23.944763440, 56.865, 366.0, 19.1311
23.988229200, 56.865, 361.0, 19.0000
24.031694960, 56.865, 378.0, 19.4422
24.075160720, 56.865, 400.0, 20.0000
24.118626480, 56.865, 362.0, 19.0263
24.162092240, 56.865, 419.0, 20.4695
24.205558000, 56.865, 380.0, 19.4936
24.249023760, 56.865, 403.0, 20.0749
24.292489520, 56.865, 417.0, 20.4206
24.335955280, 56.865, 423.0, 20.5670
24.379421040, 56.865, 494.0, 22.2261
24.422886800, 56.865, 540.0, 23.2379
24.466352560, 56.865, 726.0, 26.9444
24.509818320, 56.865, 1032.0, 32.1248
24.553284080, 56.865, 1027.0, 32.0468
24.596749840, 56.865, 871.0, 29.5127
24.640215600, 56.865, 657.0, 25.6320
24.683681360, 56.865, 457.0, 21.3776
24.727147120, 56.865, 423.0, 20.5670
24.770612880, 56.865, 400.0, 20.0000
24.814078640, 56.865, 386.0, 19.6469
24.857544400, 56.865, 356.0, 18.8680
24.901010160, 56.865, 368.0, 19.1833
24.944475920, 56.865, 374.0, 19.3391
24.987941680, 56.865, 381.0, 19.5192
25.031407440, 56.865, 385.0, 19.6214
25.074873200, 56.865, 332.0, 18.2209
25.118338960, 56.865, 353.0, 18.7883
25.161804720, 56.865, 379.0, 19.4679
25.205270480, 56.865, 396.0, 19.8997
25.248736240, 56.865, 381.0, 19.5192
25.292202000, 56.865, 340.0, 18.4391
25.335667760, 56.865, 377.0, 19.4165
25.379133520, 56.865, 344.0, 18.5472
25.422599280, 56.865, 368.0, 19.1833
25.466065040, 56.865, 371.0, 19.2614
25.509530800, 56.865, 390.0, 19.7484
25.552996560, 56.865, 399.0, 19.9750
25.596462320, 56.865, 383.0, 19.5704
25.639928080, 56.865, 353.0, 18.7883
25.683393840, 56.865, 378.0, 19.4422
25.726859600, 56.865, 377.0, 19.4165
25.770325360, 56.865, 363.0, 19.0526
25.813791120, 56.865, 388.0, 19.6977
25.857256880, 56.865, 382.0, 19.5448
25.900722640, 56.865, 390.0, 19.7484
25.944188400, 56.865, 368.0, 19.1833
25.987654160, 56.865, 353.0, 18.7883
26.031119920, 56.865, 397.0, 19.9249
26.074585680, 56.865, 373.0, 19.3132
26.118051440, 56.865, 383.0, 19.5704
26.161517200, 56.865, 373.0, 19.3132
26.204982960, 56.865, 378.0, 19.4422
26.248448720, 56.865, 422.0, 20.5426
26.291914480, 56.865, 397.0, 19.9249
26.335380240, 56.865, 363.0, 19.0526
26.378846000, 56.865, 368.0, 19.1833
26.422311760, 56.865, 350.0, 18.7083
26.465777520, 56.865, 398.0, 19.9499
26.509243280, 56.865, 387.0, 19.6723
26.552709040, 56.865, 392.0, 19.7990
26.596174800, 56.865, 414.0, 20.3470
26.639640560, 56.865, 404.0, 20.0998
26.683106320, 56.865, 387.0, 19.6723
26.726572080, 56.865, 372.0, 19.2873
26.770037840, 56.865, 381.0, 19.5192
26.813503600, 56.865, 403.0, 20.0749
26.856969360, 56.865, 435.0, 20.8567
26.900435120, 56.865, 391.0, 19.7737
26.943900880, 56.865, 423.0, 20.5670
26.987366640, 56.865, 485.0, 22.0227
27.030832400, 56.865, 508.0, 22.5389
27.074298160, 56.865, 502.0, 22.4054
27.117763920, 56.865, 529.0, 23.0000
27.161229680, 56.865, 555.0, 23.5584
27.204695440, 56.865, 532.0, 23.0651
27.248161200, 56.865, 496.0, 22.2711
27.291626960, 56.865, 470.0, 21.6795
27.335092720, 56.865, 445.0, 21.0950
27.378558480, 56.865, 372.0, 19.2873
27.422024240, 56.865, 380.0, 19.4936
27.465490000, 56.865, 417.0, 20.4206
27.508955760, 56.865, 414.0, 20.3470
27.552421520, 56.865, 396.0, 19.8997
27.595887280, 56.865, 404.0, 20.0998
27.639353040, 56.865, 348.0, 18.6548
27.682818800, 56.865, 385.0, 19.6214
27.726284560, 56.865, 379.0, 19.4679
27.769750320, 56.865, 372.0, 19.2873
27.813216080, 56.865, 374.0, 19.3391
27.856681840, 56.865, 407.0, 20.1742
27.900147600, 56.865, 373.0, 19.3132
27.943613360, 56.865, 391.0, 19.7737
27.987079120, 56.865, 386.0, 19.6469
28.030544880, 56.865, 401.0, 20.0250
28.074010640, 56.865, 432.0, 20.7846
28.117476400, 56.865, 442.0, 21.0238
28.160942160, 56.865, 505.0, 22.4722
28.204407920, 56.865, 562.0, 23.7065
28.247873680, 56.865, 701.0, 26.4764
28.291339440, 56.865, 1012.0, 31.8119
28.334805200, 56.865, 1526.0, 39.0640
28.378270960, 56.865, 1737.0, 41.6773
28.421736720, 56.865, 1307.0, 36.1525
28.465202480, 56.865, 875.0, 29.5804
28.508668240, 56.865, 518.0, 22.7596
28.552134000, 56.865, 492.0, 22.1811
28.595599760, 56.865, 433.0, 20.8087
28.639065520, 56.865, 372.0, 19.2873
28.682531280, 56.865, 351.0, 18.7350
28.725997040, 56.865, 402.0, 20.0499
28.769462800, 56.865, 371.0, 19.2614
28.812928560, 56.865, 329.0, 18.1384
28.856394320, 56.865, 340.0, 18.4391
28.899860080, 56.865, 358.0, 18.9209
28.943325840, 56.865, 339.0, 18.4120
28.986791600, 56.865, 390.0, 19.7484
29.030257360, 56.865, 360.0, 18.9737
29.073723120, 56.865, 370.0, 19.2354
29.117188880, 56.865, 346.0, 18.6011
29.160654640, 56.865, 345.0, 18.5742
29.204120400, 56.865, 333.0, 18.2483
29.247586160, 56.865, 317.0, 17.8045
29.291051920, 56.865, 330.0, 18.1659
29.334517680, 56.865, 394.0, 19.8494
29.377983440, 56.865, 329.0, 18.1384
29.421449200, 56.865, 362.0, 19.0263
29.464914960, 56.865, 382.0, 19.5448
29.508380720, 56.865, 368.0, 19.1833
29.551846480, 56.865, 350.0, 18.7083
29.595312240, 56.865, 350.0, 18.7083
29.638778000, 56.865, 306.0, 17.4929
29.682243760, 56.865, 348.0, 18.6548
29.725709520, 56.865, 362.0, 19.0263
29.769175280, 56.865, 345.0, 18.5742
29.812641040, 56.865, 334.0, 18.2757
29.856106800, 56.865, 336.0, 18.3303
29.899572560, 56.865, 338.0, 18.3848
29.943038320, 56.865, 341.0, 18.4662
29.986504080, 56.865, 390.0, 19.7484
30.029969840, 56.865, 355.0, 18.8414
30.073435600, 56.865, 365.0, 19.1050
30.116901360, 56.865, 407.0, 20.1742
30.160367120, 56.865, 460.0, 21.4476
30.203832880, 56.865, 478.0, 21.8632
30.247298640, 56.865, 543.0, 23.3024
30.290764400, 56.865, 525.0, 22.9129
30.334230160, 56.865, 572.0, 23.9165
30.377695920, 56.865, 572.0, 23.9165
30.421161680, 56.865, 504.0, 22.4499
30.464627440, 56.865, 519.0, 22.7816
30.508093200, 56.865, 499.0, 22.3383
30.551558960, 56.865, 452.0, 21.2603
30.595024720, 56.865, 432.0, 20.7846
30.638490480, 56.865, 380.0, 19.4936
30.681956240, 56.865, 395.0, 19.8746
30.725422000, 56.865, 404.0, 20.0998
30.768887760, 56.865, 382.0, 19.5448
30.812353520, 56.865, 369.0, 19.2094
30.855819280, 56.865, 387.0, 19.6723
30.899285040, 56.865, 340.0, 18.4391
30.942750800, 56.865, 370.0, 19.2354
30.986216560, 56.865, 361.0, 19.0000
31.029682320, 56.865, 352.0, 18.7617
31.073148080, 56.865, 329.0, 18.1384
31.116613840, 56.865, 322.0, 17.9444
31.160079600, 56.865, 362.0, 19.0263
31.203545360, 56.865, 335.0, 18.3030
31.247011120, 56.865, 359.0, 18.9473
31.290476880, 56.865, 361.0, 19.0000
31.333942640, 56.865, 367.0, 19.1572
31.377408400, 56.865, 342.0, 18.4932
31.420874160, 56.865, 370.0, 19.2354
31.464339920, 56.865, 345.0, 18.5742
31.507805680, 56.865, 366.0, 19.1311
31.551271440, 56.865, 349.0, 18.6815
31.594737200, 56.865, 420.0, 20.4939
31.638202960, 56.865, 480.0, 21.9089
31.681668720, 56.865, 651.0, 25.5147
31.725134480, 56.865, 984.0, 31.3688
31.768600240, 56.865, 1627.0, 40.3361
31.812066000, 56.865, 1875.0, 43.3013
31.855531760, 56.865, 1592.0, 39.8999
31.898997520, 56.865, 1163.0, 34.1028
31.942463280, 56.865, 705.0, 26.5518
31.985929040, 56.865, 470.0, 21.6795
32.029394800, 56.865, 428.0, 20.6882
32.072860560, 56.865, 374.0, 19.3391
32.116326320, 56.865, 388.0, 19.6977
32.159792080, 56.865, 354.0, 18.8149
32.203257840, 56.865, 372.0, 19.2873
32.246723600, 56.865, 378.0, 19.4422
32.290189360, 56.865, 354.0, 18.8149
32.333655120, 56.865, 338.0, 18.3848
32.377120880, 56.865, 338.0, 18.3848
32.420586640, 56.865, 324.0, 18.0000
32.464052400, 56.865, 319.0, 17.8606
32.507518160, 56.865, 314.0, 17.7200
32.550983920, 56.865, 314.0, 17.7200
32.594449680, 56.865, 322.0, 17.9444
32.637915440, 56.865, 313.0, 17.6918
32.681381200, 56.865, 300.0, 17.3205
32.724846960, 56.865, 262.0, 16.1864
32.768312720, 56.865, 304.0, 17.4356
32.811778480, 56.865, 275.0, 16.5831
32.855244240, 56.865, 323.0, 17.9722
32.898710000, 56.865, 278.0, 16.6733
32.942175760, 56.865, 290.0, 17.0294
32.985641520, 56.865, 355.0, 18.8414
33.029107280, 56.865, 324.0, 18.0000
33.072573040, 56.865, 307.0, 17.5214
33.116038800, 56.865, 293.0, 17.1172
33.159504560, 56.865, 294.0, 17.1464
33.202970320, 56.865, 306.0, 17.4929
33.246436080, 56.865, 275.0, 16.5831
33.289901840, 56.865, 306.0, 17.4929
33.333367600, 56.865, 309.0, 17.5784
33.376833360, 56.865, 281.0, 16.7631
33.420299120, 56.865, 321.0, 17.9165
33.463764880, 56.865, 306.0, 17.4929
33.507230640, 56.865, 308.0, 17.5499
33.550696400, 56.865, 278.0, 16.6733
33.594162160, 56.865, 291.0, 17.0587
33.637627920, 56.865, 281.0, 16.7631
33.681093680, 56.865, 308.0, 17.5499
33.724559440, 56.865, 307.0, 17.5214
33.768025200, 56.865, 293.0, 17.1172
33.811490960, 56.865, 306.0, 17.4929
33.854956720, 56.865, 313.0, 17.6918
33.898422480, 56.865, 288.0, 16.9706
33.941888240, 56.865, 271.0, 16.4621
33.985354000, 56.865, 307.0, 17.5214
34.028819760, 56.865, 244.0, 15.6205
34.072285520, 56.865, 286.0, 16.9115
34.115751280, 56.865, 248.0, 15.7480
34.159217040, 56.865, 279.0, 16.7033
34.202682800, 56.865, 295.0, 17.1756
34.246148560, 56.865, 285.0, 16.8819
34.289614320, 56.865, 267.0, 16.3401
34.333080080, 56.865, 332.0, 18.2209
34.376545840, 56.865, 266.0, 16.3095
34.420011600, 56.865, 273.0, 16.5227
34.463477360, 56.865, 295.0, 17.1756
34.506943120, 56.865, 271.0, 16.4621
34.550408880, 56.865, 304.0, 17.4356
34.593874640, 56.865, 317.0, 17.8045
34.637340400, 56.865, 327.0, 18.0831
34.680806160, 56.865, 306.0, 17.4929
34.724271920, 56.865, 316.0, 17.7764
34.767737680, 56.865, 327.0, 18.0831
34.811203440, 56.865, 388.0, 19.6977
34.854669200, 56.865, 568.0, 23.8328
34.898134960, 56.865, 834.0, 28.8791
34.941600720, 56.865, 1107.0, 33.2716
34.985066480, 56.865, 1161.0, 34.0735
35.028532240, 56.865, 1018.0, 31.9061
35.071998000, 56.865, 705.0, 26.5518
35.115463760, 56.865, 502.0, 22.4054
35.158929520, 56.865, 449.0, 21.1896
35.202395280, 56.865, 370.0, 19.2354
35.245861040, 56.865, 312.0, 17.6635
35.289326800, 56.865, 323.0, 17.9722
35.332792560, 56.865, 309.0, 17.5784
35.376258320, 56.865, 400.0, 20.0000
35.419724080, 56.865, 381.0, 19.5192
35.463189840, 56.865, 383.0, 19.5704
35.506655600, 56.865, 304.0, 17.4356
35.550121360, 56.865, 324.0, 18.0000
35.593587120, 56.865, 302.0, 17.3781
35.637052880, 56.865, 305.0, 17.4642
35.680518640, 56.865, 278.0, 16.6733
35.723984400, 56.865, 294.0, 17.1464
35.767450160, 56.865, 238.0, 15.4272
35.810915920, 56.865, 275.0, 16.5831
35.854381680, 56.865, 222.0, 14.8997
35.897847440, 56.865, 254.0, 15.9374
35.941313200, 56.865, 268.0, 16.3707
35.984778960, 56.865, 228.0, 15.0997
36.028244720, 56.865, 258.0, 16.0624
36.071710480, 56.865, 299.0, 17.2916
36.115176240, 56.865, 273.0, 16.5227
36.158642000, 56.865, 259.0, 16.0935
36.202107760, 56.865, 246.0, 15.6844
36.245573520, 56.865, 258.0, 16.0624
36.289039280, 56.865, 256.0, 16.0000
36.332505040, 56.865, 235.0, 15.3297
36.375970800, 56.865, 277.0, 16.6433
36.419436560, 56.865, 231.0, 15.1987
36.462902320, 56.865, 264.0, 16.2481
36.506368080, 56.865, 287.0, 16.9411
36.549833840, 56.865, 275.0, 16.5831
36.593299600, 56.865, 238.0, 15.4272
36.636765360, 56.865, 242.0, 15.5563
36.680231120, 56.865, 281.0, 16.7631
36.723696880, 56.865, 267.0, 16.3401
36.767162640, 56.865, 250.0, 15.8114
36.810628400, 56.865, 235.0, 15.3297
36.854094160, 56.865, 249.0, 15.7797
36.897559920, 56.865, 247.0, 15.7162
36.941025680, 56.865, 253.0, 15.9060
36.984491440, 56.865, 233.0, 15.2643
37.027957200, 56.865, 272.0, 16.4924
37.071422960, 56.865, 256.0, 16.0000
37.114888720, 56.865, 256.0, 16.0000
37.158354480, 56.865, 243.0, 15.5885
37.201820240, 56.865, 241.0, 15.5242
37.245286000, 56.865, 256.0, 16.0000
37.288751760, 56.865, 263.0, 16.2173
37.332217520, 56.865, 249.0, 15.7797
37.375683280, 56.865, 260.0, 16.1245
37.419149040, 56.865, 260.0, 16.1245
37.462614800, 56.865, 241.0, 15.5242
37.506080560, 56.865, 227.0, 15.0665
37.549546320, 56.865, 250.0, 15.8114
37.593012080, 56.865, 224.0, 14.9666
37.636477840, 56.865, 240.0, 15.4919
37.679943600, 56.865, 258.0, 16.0624
37.723409360, 56.865, 229.0, 15.1327
37.766875120, 56.865, 269.0, 16.4012
37.810340880, 56.865, 223.0, 14.9332
37.853806640, 56.865, 263.0, 16.2173
37.897272400, 56.865, 255.0, 15.9687
37.940738160, 56.865, 229.0, 15.1327
37.984203920, 56.865, 245.0, 15.6525
38.027669680, 56.865, 219.0, 14.7986
38.071135440, 56.865, 246.0, 15.6844
38.114601200, 56.865, 249.0, 15.7797
38.158066960, 56.865, 225.0, 15.0000
38.201532720, 56.865, 212.0, 14.5602
38.244998480, 56.865, 279.0, 16.7033
38.288464240, 56.865, 227.0, 15.0665
38.331930000, 56.865, 235.0, 15.3297
38.375395760, 56.865, 224.0, 14.9666
38.418861520, 56.865, 241.0, 15.5242
38.462327280, 56.865, 250.0, 15.8114
38.505793040, 56.865, 281.0, 16.7631
38.549258800, 56.865, 261.0, 16.1555
38.592724560, 56.865, 260.0, 16.1245
38.636190320, 56.865, 322.0, 17.9444
38.679656080, 56.865, 291.0, 17.0587
38.723121840, 56.865, 260.0, 16.1245
38.766587600, 56.865, 236.0, 15.3623
38.810053360, 56.865, 245.0, 15.6525
38.853519120, 56.865, 254.0, 15.9374
38.896984880, 56.865, 237.0, 15.3948
38.940450640, 56.865, 242.0, 15.5563
38.983916400, 56.865, 254.0, 15.9374
39.027382160, 56.865, 267.0, 16.3401
39.070847920, 56.865, 231.0, 15.1987
39.114313680, 56.865, 235.0, 15.3297
39.157779440, 56.865, 241.0, 15.5242
39.201245200, 56.865, 240.0, 15.4919
39.244710960, 56.865, 262.0, 16.1864
39.288176720, 56.865, 237.0, 15.3948
39.331642480, 56.865, 259.0, 16.0935
39.375108240, 56.865, 224.0, 14.9666
39.418574000, 56.865, 238.0, 15.4272
39.462039760, 56.865, 226.0, 15.0333
39.505505520, 56.865, 256.0, 16.0000
39.548971280, 56.865, 256.0, 16.0000
39.592437040, 56.865, 254.0, 15.9374
39.635902800, 56.865, 240.0, 15.4919
39.679368560, 56.865, 231.0, 15.1987
39.722834320, 56.865, 261.0, 16.1555
39.766300080, 56.865, 243.0, 15.5885
39.809765840, 56.865, 240.0, 15.4919
39.853231600, 56.865, 264.0, 16.2481
39.896697360, 56.865, 290.0, 17.0294
39.940163120, 56.865, 224.0, 14.9666
39.983628880, 56.865, 253.0, 15.9060
40.027094640, 56.865, 273.0, 16.5227
40.070560400, 56.865, 262.0, 16.1864
40.114026160, 56.865, 257.0, 16.0312
40.157491920, 56.865, 262.0, 16.1864
40.200957680, 56.865, 333.0, 18.2483
40.244423440, 56.865, 333.0, 18.2483
40.287889200, 56.865, 301.0, 17.3494
40.331354960, 56.865, 349.0, 18.6815
40.374820720, 56.865, 433.0, 20.8087
40.418286480, 56.865, 656.0, 25.6125
40.461752240, 56.865, 1154.0, 33.9706
40.505218000, 56.865, 1868.0, 43.2204
40.548683760, 56.865, 2223.0, 47.1487
40.592149520, 56.865, 2342.0, 48.3942
40.635615280, 56.865, 2051.0, 45.2880
40.679081040, 56.865, 1556.0, 39.4462
40.722546800, 56.865, 1113.0, 33.3617
40.766012560, 56.865, 673.0, 25.9422
40.809478320, 56.865, 415.0, 20.3715
40.852944080, 56.865, 352.0, 18.7617
40.896409840, 56.865, 315.0, 17.7482
40.939875600, 56.865, 261.0, 16.1555
40.983341360, 56.865, 278.0, 16.6733
41.026807120, 56.865, 286.0, 16.9115
41.070272880, 56.865, 243.0, 15.5885
41.113738640, 56.865, 236.0, 15.3623
41.157204400, 56.865, 245.0, 15.6525
41.200670160, 56.865, 238.0, 15.4272
41.244135920, 56.865, 263.0, 16.2173
41.287601680, 56.865, 212.0, 14.5602
41.331067440, 56.865, 255.0, 15.9687
41.374533200, 56.865, 244.0, 15.6205
41.417998960, 56.865, 244.0, 15.6205
41.461464720, 56.865, 231.0, 15.1987
41.504930480, 56.865, 239.0, 15.4596
41.548396240, 56.865, 238.0, 15.4272
41.591862000, 56.865, 255.0, 15.9687
41.635327760, 56.865, 266.0, 16.3095
41.678793520, 56.865, 249.0, 15.7797
41.722259280, 56.865, 234.0, 15.2971
41.765725040, 56.865, 226.0, 15.0333
41.809190800, 56.865, 257.0, 16.0312
41.852656560, 56.865, 248.0, 15.7480
41.896122320, 56.865, 240.0, 15.4919
41.939588080, 56.865, 248.0, 15.7480
41.983053840, 56.865, 239.0, 15.4596
42.026519600, 56.865, 252.0, 15.8745
42.069985360, 56.865, 229.0, 15.1327
42.113451120, 56.865, 248.0, 15.7480
42.156916880, 56.865, 237.0, 15.3948
42.200382640, 56.865, 256.0, 16.0000
42.243848400, 56.865, 230.0, 15.1658
42.287314160, 56.865, 261.0, 16.1555
42.330779920, 56.865, 231.0, 15.1987
42.374245680, 56.865, 219.0, 14.7986
42.417711440, 56.865, 237.0, 15.3948
42.461177200, 56.865, 227.0, 15.0665
42.504642960, 56.865, 208.0, 14.4222
42.548108720, 56.865, 263.0, 16.2173
42.591574480, 56.865, 221.0, 14.8661
42.635040240, 56.865, 219.0, 14.7986
42.678506000, 56.865, 213.0, 14.5945
42.721971760, 56.865, 242.0, 15.5563
42.765437520, 56.865, 204.0, 14.2829
42.808903280, 56.865, 278.0, 16.6733
42.852369040, 56.865, 247.0, 15.7162
42.895834800, 56.865, 256.0, 16.0000
42.939300560, 56.865, 300.0, 17.3205
42.982766320, 56.865, 368.0, 19.1833
43.026232080, 56.865, 556.0, 23.5797
43.069697840, 56.865, 681.0, 26.0960
43.113163600, 56.865, 747.0, 27.3313
43.156629360, 56.865, 720.0, 26.8328
43.200095120, 56.865, 646.0, 25.4165
43.243560880, 56.865, 574.0, 23.9583
43.287026640, 56.865, 434.0, 20.8327
43.330492400, 56.865, 339.0, 18.4120
43.373958160, 56.865, 301.0, 17.3494
43.417423920, 56.865, 271.0, 16.4621
43.460889680, 56.865, 241.0, 15.5242
43.504355440, 56.865, 277.0, 16.6433
43.547821200, 56.865, 238.0, 15.4272
43.591286960, 56.865, 228.0, 15.0997
43.634752720, 56.865, 224.0, 14.9666
43.678218480, 56.865, 229.0, 15.1327
43.721684240, 56.865, 226.0, 15.0333
43.765150000, 56.865, 228.0, 15.0997
43.808615760, 56.865, 247.0, 15.7162
43.852081520, 56.865, 216.0, 14.6969
43.895547280, 56.865, 252.0, 15.8745
43.939013040, 56.865, 213.0, 14.5945
43.982478800, 56.865, 228.0, 15.0997
44.025944560, 56.865, 236.0, 15.3623
44.069410320, 56.865, 230.0, 15.1658
44.112876080, 56.865, 239.0, 15.4596
44.156341840, 56.865, 241.0, 15.5242
44.199807600, 56.865, 231.0, 15.1987
44.243273360, 56.865, 225.0, 15.0000
44.286739120, 56.865, 220.0, 14.8324
44.330204880, 56.865, 212.0, 14.5602
44.373670640, 56.865, 235.0, 15.3297
44.417136400, 56.865, 201.0, 14.1774
44.460602160, 56.865, 211.0, 14.5258
44.504067920, 56.865, 228.0, 15.0997
44.547533680, 56.865, 240.0, 15.4919
44.590999440, 56.865, 213.0, 14.5945
44.634465200, 56.865, 230.0, 15.1658
44.677930960, 56.865, 201.0, 14.1774
44.721396720, 56.865, 198.0, 14.0712
44.764862480, 56.865, 220.0, 14.8324
44.808328240, 56.865, 192.0, 13.8564
44.851794000, 56.865, 208.0, 14.4222
44.895259760, 56.865, 249.0, 15.7797
44.938725520, 56.865, 195.0, 13.9642
44.982191280, 56.865, 210.0, 14.4914
45.025657040, 56.865, 204.0, 14.2829
45.069122800, 56.865, 201.0, 14.1774
45.112588560, 56.865, 237.0, 15.3948
45.156054320, 56.865, 202.0, 14.2127
45.199520080, 56.865, 247.0, 15.7162
45.242985840, 56.865, 231.0, 15.1987
45.286451600, 56.865, 250.0, 15.8114
45.329917360, 56.865, 230.0, 15.1658
45.373383120, 56.865, 227.0, 15.0665
45.416848880, 56.865, 252.0, 15.8745
45.460314640, 56.865, 257.0, 16.0312
45.503780400, 56.865, 253.0, 15.9060
45.547246160, 56.865, 263.0, 16.2173
45.590711920, 56.865, 262.0, 16.1864
45.634177680, 56.865, 281.0, 16.7631
45.677643440, 56.865, 261.0, 16.1555
45.721109200, 56.865, 244.0, 15.6205
45.764574960, 56.865, 237.0, 15.3948
45.808040720, 56.865, 216.0, 14.6969
45.851506480, 56.865, 220.0, 14.8324
45.894972240, 56.865, 208.0, 14.4222
45.938438000, 56.865, 187.0, 13.6748
45.981903760, 56.865, 200.0, 14.1421
46.025369520, 56.865, 208.0, 14.4222
46.068835280, 56.865, 203.0, 14.2478
46.112301040, 56.865, 211.0, 14.5258
46.155766800, 56.865, 201.0, 14.1774
46.199232560, 56.865, 212.0, 14.5602
46.242698320, 56.865, 198.0, 14.0712
46.286164080, 56.865, 201.0, 14.1774
46.329629840, 56.865, 246.0, 15.6844
46.373095600, 56.865, 218.0, 14.7648
46.416561360, 56.865, 210.0, 14.4914
46.460027120, 56.865, 211.0, 14.5258
46.503492880, 56.865, 193.0, 13.8924
46.546958640, 56.865, 196.0, 14.0000
46.590424400, 56.865, 213.0, 14.5945
46.633890160, 56.865, 178.0, 13.3417
46.677355920, 56.865, 168.0, 12.9615
46.720821680, 56.865, 180.0, 13.4164
46.764287440, 56.865, 191.0, 13.8203
46.807753200, 56.865, 184.0, 13.5647
46.851218960, 56.865, 184.0, 13.5647
46.894684720, 56.865, 197.0, 14.0357
46.938150480, 56.865, 206.0, 14.3527
46.981616240, 56.865, 219.0, 14.7986
47.025082000, 56.865, 208.0, 14.4222
47.068547760, 56.865, 182.0, 13.4907
47.112013520, 56.865, 207.0, 14.3875
47.155479280, 56.865, 191.0, 13.8203
47.198945040, 56.865, 189.0, 13.7477
47.242410800, 56.865, 217.0, 14.7309
47.285876560, 56.865, 193.0, 13.8924
47.329342320, 56.865, 182.0, 13.4907
47.372808080, 56.865, 222.0, 14.8997
47.416273840, 56.865, 194.0, 13.9284
47.459739600, 56.865, 180.0, 13.4164
47.503205360, 56.865, 198.0, 14.0712
47.546671120, 56.865, 211.0, 14.5258
47.590136880, 56.865, 170.0, 13.0384
47.633602640, 56.865, 207.0, 14.3875
47.677068400, 56.865, 171.0, 13.0767
47.720534160, 56.865, 182.0, 13.4907
47.763999920, 56.865, 218.0, 14.7648
47.807465680, 56.865, 205.0, 14.3178
47.850931440, 56.865, 212.0, 14.5602
47.894397200, 56.865, 219.0, 14.7986
47.937862960, 56.865, 209.0, 14.4568
47.981328720, 56.865, 186.0, 13.6382
48.024794480, 56.865, 217.0, 14.7309
48.068260240, 56.865, 194.0, 13.9284
48.111726000, 56.865, 205.0, 14.3178
48.155191760, 56.865, 199.0, 14.1067
48.198657520, 56.865, 193.0, 13.8924
48.242123280, 56.865, 180.0, 13.4164
48.285589040, 56.865, 194.0, 13.9284
48.329054800, 56.865, 179.0, 13.3791
48.372520560, 56.865, 217.0, 14.7309
48.415986320, 56.865, 209.0, 14.4568
48.459452080, 56.865, 198.0, 14.0712
48.502917840, 56.865, 186.0, 13.6382
48.546383600, 56.865, 170.0, 13.0384
48.589849360, 56.865, 176.0, 13.2665
48.633315120, 56.865, 175.0, 13.2288
48.676780880, 56.865, 174.0, 13.1909
48.720246640, 56.865, 199.0, 14.1067
48.763712400, 56.865, 203.0, 14.2478
48.807178160, 56.865, 192.0, 13.8564
48.850643920, 56.865, 175.0, 13.2288
48.894109680, 56.865, 180.0, 13.4164
48.937575440, 56.865, 197.0, 14.0357
48.981041200, 56.865, 204.0, 14.2829
49.024506960, 56.865, 179.0, 13.3791
49.067972720, 56.865, 195.0, 13.9642
49.111438480, 56.865, 193.0, 13.8924
49.154904240, 56.865, 178.0, 13.3417
49.198370000, 56.865, 179.0, 13.3791
49.241835760, 56.865, 193.0, 13.8924
49.285301520, 56.865, 184.0, 13.5647
49.328767280, 56.865, 176.0, 13.2665
49.372233040, 56.865, 214.0, 14.6287
49.415698800, 56.865, 185.0, 13.6015
49.459164560, 56.865, 209.0, 14.4568
49.502630320, 56.865, 182.0, 13.4907
49.546096080, 56.865, 186.0, 13.6382
49.589561840, 56.865, 203.0, 14.2478
49.633027600, 56.865, 220.0, 14.8324
49.676493360, 56.865, 188.0, 13.7113
49.719959120, 56.865, 174.0, 13.1909
49.763424880, 56.865, 216.0, 14.6969
49.806890640, 56.865, 204.0, 14.2829
49.850356400, 56.865, 193.0, 13.8924
49.893822160, 56.865, 179.0, 13.3791
49.937287920, 56.865, 227.0, 15.0665
49.980753680, 56.865, 176.0, 13.2665
50.024219440, 56.865, 244.0, 15.6205
50.067685200, 56.865, 215.0, 14.6629
50.111150960, 56.865, 320.0, 17.8885
50.154616720, 56.865, 317.0, 17.8045
50.198082480, 56.865, 355.0, 18.8414
50.241548240, 56.865, 345.0, 18.5742
50.285014000, 56.865, 329.0, 18.1384
50.328479760, 56.865, 315.0, 17.7482
50.371945520, 56.865, 291.0, 17.0587
50.415411280, 56.865, 275.0, 16.5831
50.458877040, 56.865, 268.0, 16.3707
50.502342800, 56.865, 239.0, 15.4596
50.545808560, 56.865, 246.0, 15.6844
50.589274320, 56.865, 269.0, 16.4012
50.632740080, 56.865, 253.0, 15.9060
50.676205840, 56.865, 269.0, 16.4012
50.719671600, 56.865, 249.0, 15.7797
50.763137360, 56.865, 244.0, 15.6205
50.806603120, 56.865, 248.0, 15.7480
50.850068880, 56.865, 236.0, 15.3623
50.893534640, 56.865, 207.0, 14.3875
50.937000400, 56.865, 212.0, 14.5602
50.980466160, 56.865, 215.0, 14.6629
51.023931920, 56.865, 219.0, 14.7986
51.067397680, 56.865, 223.0, 14.9332
51.110863440, 56.865, 205.0, 14.3178
51.154329200, 56.865, 198.0, 14.0712
51.197794960, 56.865, 183.0, 13.5277
51.241260720, 56.865, 198.0, 14.0712
51.284726480, 56.865, 203.0, 14.2478
51.328192240, 56.865, 198.0, 14.0712
51.371658000, 56.865, 170.0, 13.0384
51.415123760, 56.865, 168.0, 12.9615
51.458589520, 56.865, 196.0, 14.0000
51.502055280, 56.865, 178.0, 13.3417
51.545521040, 56.865, 183.0, 13.5277
51.588986800, 56.865, 183.0, 13.5277
51.632452560, 56.865, 187.0, 13.6748
51.675918320, 56.865, 189.0, 13.7477
51.719384080, 56.865, 140.0, 11.8322
51.762849840, 56.865, 186.0, 13.6382
51.806315600, 56.865, 186.0, 13.6382
51.849781360, 56.865, 182.0, 13.4907
51.893247120, 56.865, 173.0, 13.1529
51.936712880, 56.865, 181.0, 13.4536
51.980178640, 56.865, 168.0, 12.9615
52.023644400, 56.865, 179.0, 13.3791
52.067110160, 56.865, 184.0, 13.5647
52.110575920, 56.865, 165.0, 12.8452
52.154041680, 56.865, 186.0, 13.6382
52.197507440, 56.865, 175.0, 13.2288
52.240973200, 56.865, 193.0, 13.8924
52.284438960, 56.865, 228.0, 15.0997
52.327904720, 56.865, 272.0, 16.4924
52.371370480, 56.865, 271.0, 16.4621
52.414836240, 56.865, 278.0, 16.6733
52.458302000, 56.865, 255.0, 15.9687
52.501767760, 56.865, 263.0, 16.2173
52.545233520, 56.865, 257.0, 16.0312
52.588699280, 56.865, 219.0, 14.7986
52.632165040, 56.865, 210.0, 14.4914
52.675630800, 56.865, 215.0, 14.6629
52.719096560, 56.865, 168.0, 12.9615
52.762562320, 56.865, 159.0, 12.6095
52.806028080, 56.865, 187.0, 13.6748
52.849493840, 56.865, 198.0, 14.0712
52.892959600, 56.865, 154.0, 12.4097
52.936425360, 56.865, 170.0, 13.0384
52.979891120, 56.865, 184.0, 13.5647
53.023356880, 56.865, 153.0, 12.3693
53.066822640, 56.865, 186.0, 13.6382
53.110288400, 56.865, 160.0, 12.6491
53.153754160, 56.865, 168.0, 12.9615
53.197219920, 56.865, 165.0, 12.8452
53.240685680, 56.865, 204.0, 14.2829
53.284151440, 56.865, 181.0, 13.4536
53.327617200, 56.865, 171.0, 13.0767
53.371082960, 56.865, 191.0, 13.8203
53.414548720, 56.865, 165.0, 12.8452
53.458014480, 56.865, 183.0, 13.5277
53.501480240, 56.865, 171.0, 13.0767
53.544946000, 56.865, 154.0, 12.4097
53.588411760, 56.865, 185.0, 13.6015
53.631877520, 56.865, 193.0, 13.8924
53.675343280, 56.865, 187.0, 13.6748
53.718809040, 56.865, 189.0, 13.7477
53.762274800, 56.865, 193.0, 13.8924
53.805740560, 56.865, 156.0, 12.4900
53.849206320, 56.865, 215.0, 14.6629
53.892672080, 56.865, 191.0, 13.8203
53.936137840, 56.865, 185.0, 13.6015
53.979603600, 56.865, 164.0, 12.8062
54.023069360, 56.865, 200.0, 14.1421
54.066535120, 56.865, 183.0, 13.5277
54.110000880, 56.865, 194.0, 13.9284
54.153466640, 56.865, 184.0, 13.5647
54.196932400, 56.865, 170.0, 13.0384
54.240398160, 56.865, 166.0, 12.8841
54.283863920, 56.865, 173.0, 13.1529
54.327329680, 56.865, 189.0, 13.7477
54.370795440, 56.865, 164.0, 12.8062
54.414261200, 56.865, 197.0, 14.0357
54.457726960, 56.865, 216.0, 14.6969
54.501192720, 56.865, 243.0, 15.5885
54.544658480, 56.865, 231.0, 15.1987
54.588124240, 56.865, 206.0, 14.3527
54.631590000, 56.865, 260.0, 16.1245
54.675055760, 56.865, 199.0, 14.1067
54.718521520, 56.865, 194.0, 13.9284
54.761987280, 56.865, 219.0, 14.7986
54.805453040, 56.865, 198.0, 14.0712
54.848918800, 56.865, 216.0, 14.6969
54.892384560, 56.865, 218.0, 14.7648
54.935850320, 56.865, 195.0, 13.9642
54.979316080, 56.865, 191.0, 13.8203
55.022781840, 56.865, 170.0, 13.0384
55.066247600, 56.865, 172.0, 13.1149
55.109713360, 56.865, 166.0, 12.8841
55.153179120, 56.865, 184.0, 13.5647
55.196644880, 56.865, 167.0, 12.9228
55.240110640, 56.865, 183.0, 13.5277
55.283576400, 56.865, 174.0, 13.1909
55.327042160, 56.865, 178.0, 13.3417
55.370507920, 56.865, 151.0, 12.2882
55.413973680, 56.865, 172.0, 13.1149
55.457439440, 56.865, 153.0, 12.3693
55.500905200, 56.865, 164.0, 12.8062
55.544370960, 56.865, 192.0, 13.8564
55.587836720, 56.865, 166.0, 12.8841
55.631302480, 56.865, 170.0, 13.0384
55.674768240, 56.865, 175.0, 13.2288
55.718234000, 56.865, 196.0, 14.0000
55.761699760, 56.865, 182.0, 13.4907
55.805165520, 56.865, 185.0, 13.6015
55.848631280, 56.865, 170.0, 13.0384
55.892097040, 56.865, 184.0, 13.5647
55.935562800, 56.865, 173.0, 13.1529
55.979028560, 56.865, 183.0, 13.5277
56.022494320, 56.865, 177.0, 13.3041
56.065960080, 56.865, 171.0, 13.0767
56.109425840, 56.865, 171.0, 13.0767
56.152891600, 56.865, 204.0, 14.2829
56.196357360, 56.865, 156.0, 12.4900
56.239823120, 56.865, 170.0, 13.0384
56.283288880, 56.865, 202.0, 14.2127
56.326754640, 56.865, 170.0, 13.0384
56.370220400, 56.865, 198.0, 14.0712
56.413686160, 56.865, 176.0, 13.2665
56.457151920, 56.865, 171.0, 13.0767
56.500617680, 56.865, 167.0, 12.9228
56.544083440, 56.865, 188.0, 13.7113
56.587549200, 56.865, 172.0, 13.1149
56.631014960, 56.865, 175.0, 13.2288
56.674480720, 56.865, 167.0, 12.9228
56.717946480, 56.865, 174.0, 13.1909
56.761412240, 56.865, 164.0, 12.8062
56.804878000, 56.865, 175.0, 13.2288
56.848343760, 56.865, 191.0, 13.8203
56.891809520, 56.865, 187.0, 13.6748
56.935275280, 56.865, 161.0, 12.6886
56.978741040, 56.865, 155.0, 12.4499
57.022206800, 56.865, 172.0, 13.1149
57.065672560, 56.865, 171.0, 13.0767
57.109138320, 56.865, 188.0, 13.7113
57.152604080, 56.865, 167.0, 12.9228
57.196069840, 56.865, 192.0, 13.8564
57.239535600, 56.865, 161.0, 12.6886
57.283001360, 56.865, 165.0, 12.8452
57.326467120, 56.865, 157.0, 12.5300
57.369932880, 56.865, 132.0, 11.4891
57.413398640, 56.865, 165.0, 12.8452
57.456864400, 56.865, 158.0, 12.5698
57.500330160, 56.865, 197.0, 14.0357
57.543795920, 56.865, 170.0, 13.0384
57.587261680, 56.865, 150.0, 12.2474
57.630727440, 56.865, 166.0, 12.8841
57.674193200, 56.865, 153.0, 12.3693
57.717658960, 56.865, 155.0, 12.4499
57.761124720, 56.865, 172.0, 13.1149
57.804590480, 56.865, 179.0, 13.3791
57.848056240, 56.865, 146.0, 12.0830
57.891522000, 56.865, 167.0, 12.9228
57.934987760, 56.865, 161.0, 12.6886
57.978453520, 56.865, 193.0, 13.8924
58.021919280, 56.865, 183.0, 13.5277
58.065385040, 56.865, 176.0, 13.2665
58.108850800, 56.865, 171.0, 13.0767
58.152316560, 56.865, 165.0, 12.8452
58.195782320, 56.865, 153.0, 12.3693
58.239248080, 56.865, 156.0, 12.4900
58.282713840, 56.865, 187.0, 13.6748
58.326179600, 56.865, 155.0, 12.4499
58.369645360, 56.865, 160.0, 12.6491
58.413111120, 56.865, 158.0, 12.5698
58.456576880, 56.865, 187.0, 13.6748
58.500042640, 56.865, 186.0, 13.6382
58.543508400, 56.865, 182.0, 13.4907
58.586974160, 56.865, 201.0, 14.1774
58.630439920, 56.865, 190.0, 13.7840
58.673905680, 56.865, 185.0, 13.6015
58.717371440, 56.865, 200.0, 14.1421
58.760837200, 56.865, 181.0, 13.4536
58.804302960, 56.865, 169.0, 13.0000
58.847768720, 56.865, 171.0, 13.0767
58.891234480, 56.865, 173.0, 13.1529
58.934700240, 56.865, 168.0, 12.9615
58.978166000, 56.865, 163.0, 12.7671
59.021631760, 56.865, 174.0, 13.1909
59.065097520, 56.865, 160.0, 12.6491
59.108563280, 56.865, 166.0, 12.8841
59.152029040, 56.865, 148.0, 12.1655
59.195494800, 56.865, 171.0, 13.0767
59.238960560, 56.865, 184.0, 13.5647
59.282426320, 56.865, 177.0, 13.3041
59.325892080, 56.865, 175.0, 13.2288
59.369357840, 56.865, 160.0, 12.6491
59.412823600, 56.865, 172.0, 13.1149
59.456289360, 56.865, 179.0, 13.3791
59.499755120, 56.865, 143.0, 11.9583
59.543220880, 56.865, 169.0, 13.0000
59.586686640, 56.865, 181.0, 13.4536
59.630152400, 56.865, 160.0, 12.6491
59.673618160, 56.865, 179.0, 13.3791
59.717083920, 56.865, 173.0, 13.1529
59.760549680, 56.865, 177.0, 13.3041
59.804015440, 56.865, 200.0, 14.1421
59.847481200, 56.865, 174.0, 13.1909
59.890946960, 56.865, 172.0, 13.1149
59.934412720, 56.865, 170.0, 13.0384