File: Data/XRD/20231019-pin-0.05%p.csv
[Measurement conditions],,,
Sample identification,20231019-pin-0.05%p,,
Comment,,,
Anode material,Cu,,
K-Alpha1 wavelength,1.540598,,
K-Alpha2 wavelength,1.544426,,
Ratio K-Alpha2/K-Alpha1,0.5,,
Divergence slit,Fixed,0.10mm,
Monochromator used,NO,,
Generator voltage,40,,
Tube current,15,,
File date and time,19/10ÔÂ/2023 21:44,,
Unit cell,,,
h k l, 0 0 0,,
Scan axis,Gonio,,
Scan range,3.016,59.9561456,
Scan step size,0.0434658,,
No. of points,1310,,
Scan type,CONTINUOUS,,
Time per step,56.865,,
[Scan points],,,
Angle, TimePerStep, Intensity, ESD
3.03773288,56.865,2653,51.5073
3.08119864,56.865,2612,51.1077
3.1246644,56.865,2556,50.5569
3.16813016,56.865,2480,49.7996
3.21159592,56.865,2502,50.02
3.25506168,56.865,2429,49.2849
3.29852744,56.865,2354,48.518
3.3419932,56.865,2193,46.8295
3.38545896,56.865,2175,46.6369
3.42892472,56.865,2043,45.1996
3.47239048,56.865,2043,45.1996
3.51585624,56.865,2025,45
3.559322,56.865,1926,43.8862
3.60278776,56.865,1846,42.9651
3.64625352,56.865,1935,43.9886
3.68971928,56.865,1803,42.4617
3.73318504,56.865,1819,42.6497
3.7766508,56.865,1749,41.821
3.82011656,56.865,1675,40.9268
3.86358232,56.865,1654,40.6694
3.90704808,56.865,1551,39.3827
3.95051384,56.865,1558,39.4715
3.9939796,56.865,1534,39.1663
4.03744536,56.865,1418,37.6563
4.08091112,56.865,1336,36.5513
4.12437688,56.865,1359,36.8646
4.16784264,56.865,1305,36.1248
4.2113084,56.865,1306,36.1386
4.25477416,56.865,1285,35.8469
4.29823992,56.865,1190,34.4964
4.34170568,56.865,1197,34.5977
4.38517144,56.865,1122,33.4963
4.4286372,56.865,1194,34.5543
4.47210296,56.865,1126,33.5559
4.51556872,56.865,1040,32.249
4.55903448,56.865,1085,32.9393
4.60250024,56.865,967,31.0966
4.645966,56.865,1051,32.4191
4.68943176,56.865,1008,31.749
4.73289752,56.865,972,31.1769
4.77636328,56.865,920,30.3315
4.81982904,56.865,926,30.4302
4.8632948,56.865,920,30.3315
4.90676056,56.865,905,30.0832
4.95022632,56.865,843,29.0345
4.99369208,56.865,825,28.7228
5.03715784,56.865,835,28.8964
5.0806236,56.865,799,28.2666
5.12408936,56.865,770,27.7489
5.16755512,56.865,747,27.3313
5.21102088,56.865,726,26.9444
5.25448664,56.865,732,27.0555
5.2979524,56.865,744,27.2764
5.34141816,56.865,725,26.9258
5.38488392,56.865,660,25.6905
5.42834968,56.865,708,26.6083
5.47181544,56.865,662,25.7294
5.5152812,56.865,685,26.1725
5.55874696,56.865,680,26.0768
5.60221272,56.865,676,26
5.64567848,56.865,662,25.7294
5.68914424,56.865,673,25.9422
5.73261,56.865,609,24.6779
5.77607576,56.865,522,22.8473
5.81954152,56.865,466,21.587
5.86300728,56.865,406,20.1494
5.90647304,56.865,469,21.6564
5.9499388,56.865,429,20.7123
5.99340456,56.865,455,21.3307
6.03687032,56.865,380,19.4936
6.08033608,56.865,419,20.4695
6.12380184,56.865,377,19.4165
6.1672676,56.865,405,20.1246
6.21073336,56.865,403,20.0749
6.25419912,56.865,400,20
6.29766488,56.865,367,19.1572
6.34113064,56.865,391,19.7737
6.3845964,56.865,354,18.8149
6.42806216,56.865,351,18.735
6.47152792,56.865,361,19
6.51499368,56.865,327,18.0831
6.55845944,56.865,305,17.4642
6.6019252,56.865,346,18.6011
6.64539096,56.865,355,18.8414
6.68885672,56.865,323,17.9722
6.73232248,56.865,388,19.6977
6.77578824,56.865,336,18.3303
6.819254,56.865,332,18.2209
6.86271976,56.865,309,17.5784
6.90618552,56.865,311,17.6352
6.94965128,56.865,325,18.0278
6.99311704,56.865,289,17
7.0365828,56.865,326,18.0555
7.08004856,56.865,343,18.5203
7.12351432,56.865,344,18.5472
7.16698008,56.865,310,17.6068
7.21044584,56.865,294,17.1464
7.2539116,56.865,286,16.9115
7.29737736,56.865,289,17
7.34084312,56.865,311,17.6352
7.38430888,56.865,344,18.5472
7.42777464,56.865,339,18.412
7.4712404,56.865,300,17.3205
7.51470616,56.865,299,17.2916
7.55817192,56.865,298,17.2627
7.60163768,56.865,350,18.7083
7.64510344,56.865,335,18.303
7.6885692,56.865,333,18.2483
7.73203496,56.865,291,17.0587
7.77550072,56.865,288,16.9706
7.81896648,56.865,318,17.8326
7.86243224,56.865,319,17.8606
7.905898,56.865,327,18.0831
7.94936376,56.865,313,17.6918
7.99282952,56.865,333,18.2483
8.03629528,56.865,335,18.303
8.07976104,56.865,341,18.4662
8.1232268,56.865,299,17.2916
8.16669256,56.865,322,17.9444
8.21015832,56.865,321,17.9165
8.25362408,56.865,323,17.9722
8.29708984,56.865,342,18.4932
8.3405556,56.865,326,18.0555
8.38402136,56.865,367,19.1572
8.42748712,56.865,323,17.9722
8.47095288,56.865,344,18.5472
8.51441864,56.865,317,17.8045
8.5578844,56.865,326,18.0555
8.60135016,56.865,313,17.6918
8.64481592,56.865,319,17.8606
8.68828168,56.865,329,18.1384
8.73174744,56.865,311,17.6352
8.7752132,56.865,313,17.6918
8.81867896,56.865,355,18.8414
8.86214472,56.865,337,18.3576
8.90561048,56.865,324,18
8.94907624,56.865,320,17.8885
8.992542,56.865,319,17.8606
9.03600776,56.865,294,17.1464
9.07947352,56.865,358,18.9209
9.12293928,56.865,364,19.0788
9.16640504,56.865,378,19.4422
9.2098708,56.865,313,17.6918
9.25333656,56.865,323,17.9722
9.29680232,56.865,327,18.0831
9.34026808,56.865,336,18.3303
9.38373384,56.865,319,17.8606
9.4271996,56.865,326,18.0555
9.47066536,56.865,308,17.5499
9.51413112,56.865,313,17.6918
9.55759688,56.865,302,17.3781
9.60106264,56.865,285,16.8819
9.6445284,56.865,311,17.6352
9.68799416,56.865,305,17.4642
9.73145992,56.865,315,17.7482
9.77492568,56.865,340,18.4391
9.81839144,56.865,343,18.5203
9.8618572,56.865,322,17.9444
9.90532296,56.865,340,18.4391
9.94878872,56.865,310,17.6068
9.99225448,56.865,333,18.2483
10.03572024,56.865,331,18.1934
10.079186,56.865,339,18.412
10.12265176,56.865,318,17.8326
10.16611752,56.865,451,21.2368
10.20958328,56.865,417,20.4206
10.25304904,56.865,432,20.7846
10.2965148,56.865,396,19.8997
10.33998056,56.865,420,20.4939
10.38344632,56.865,408,20.199
10.42691208,56.865,417,20.4206
10.47037784,56.865,305,17.4642
10.5138436,56.865,328,18.1108
10.55730936,56.865,340,18.4391
10.60077512,56.865,305,17.4642
10.64424088,56.865,349,18.6815
10.68770664,56.865,320,17.8885
10.7311724,56.865,356,18.868
10.77463816,56.865,286,16.9115
10.81810392,56.865,284,16.8523
10.86156968,56.865,327,18.0831
10.90503544,56.865,300,17.3205
10.9485012,56.865,323,17.9722
10.99196696,56.865,317,17.8045
11.03543272,56.865,317,17.8045
11.07889848,56.865,283,16.8226
11.12236424,56.865,302,17.3781
11.16583,56.865,296,17.2047
11.20929576,56.865,283,16.8226
11.25276152,56.865,322,17.9444
11.29622728,56.865,275,16.5831
11.33969304,56.865,301,17.3494
11.3831588,56.865,275,16.5831
11.42662456,56.865,290,17.0294
11.47009032,56.865,302,17.3781
11.51355608,56.865,286,16.9115
11.55702184,56.865,298,17.2627
11.6004876,56.865,323,17.9722
11.64395336,56.865,278,16.6733
11.68741912,56.865,335,18.303
11.73088488,56.865,301,17.3494
11.77435064,56.865,307,17.5214
11.8178164,56.865,327,18.0831
11.86128216,56.865,333,18.2483
11.90474792,56.865,336,18.3303
11.94821368,56.865,297,17.2337
11.99167944,56.865,304,17.4356
12.0351452,56.865,299,17.2916
12.07861096,56.865,296,17.2047
12.12207672,56.865,320,17.8885
12.16554248,56.865,294,17.1464
12.20900824,56.865,283,16.8226
12.252474,56.865,311,17.6352
12.29593976,56.865,319,17.8606
12.33940552,56.865,316,17.7764
12.38287128,56.865,306,17.4929
12.42633704,56.865,307,17.5214
12.4698028,56.865,282,16.7929
12.51326856,56.865,309,17.5784
12.55673432,56.865,309,17.5784
12.60020008,56.865,282,16.7929
12.64366584,56.865,302,17.3781
12.6871316,56.865,264,16.2481
12.73059736,56.865,293,17.1172
12.77406312,56.865,270,16.4317
12.81752888,56.865,301,17.3494
12.86099464,56.865,281,16.7631
12.9044604,56.865,287,16.9411
12.94792616,56.865,284,16.8523
12.99139192,56.865,294,17.1464
13.03485768,56.865,249,15.7797
13.07832344,56.865,278,16.6733
13.1217892,56.865,293,17.1172
13.16525496,56.865,257,16.0312
13.20872072,56.865,272,16.4924
13.25218648,56.865,329,18.1384
13.29565224,56.865,298,17.2627
13.339118,56.865,286,16.9115
13.38258376,56.865,287,16.9411
13.42604952,56.865,333,18.2483
13.46951528,56.865,366,19.1311
13.51298104,56.865,388,19.6977
13.5564468,56.865,401,20.025
13.59991256,56.865,406,20.1494
13.64337832,56.865,374,19.3391
13.68684408,56.865,338,18.3848
13.73030984,56.865,367,19.1572
13.7737756,56.865,395,19.8746
13.81724136,56.865,433,20.8087
13.86070712,56.865,451,21.2368
13.90417288,56.865,437,20.9045
13.94763864,56.865,610,24.6982
13.9911044,56.865,647,25.4362
14.03457016,56.865,807,28.4077
14.07803592,56.865,1071,32.7261
14.12150168,56.865,1513,38.8973
14.16496744,56.865,2256,47.4974
14.2084332,56.865,2985,54.6352
14.25189896,56.865,2211,47.0213
14.29536472,56.865,1057,32.5115
14.33883048,56.865,544,23.3238
14.38229624,56.865,437,20.9045
14.425762,56.865,390,19.7484
14.46922776,56.865,377,19.4165
14.51269352,56.865,358,18.9209
14.55615928,56.865,319,17.8606
14.59962504,56.865,306,17.4929
14.6430908,56.865,319,17.8606
14.68655656,56.865,296,17.2047
14.73002232,56.865,279,16.7033
14.77348808,56.865,307,17.5214
14.81695384,56.865,282,16.7929
14.8604196,56.865,287,16.9411
14.90388536,56.865,281,16.7631
14.94735112,56.865,260,16.1245
14.99081688,56.865,312,17.6635
15.03428264,56.865,294,17.1464
15.0777484,56.865,310,17.6068
15.12121416,56.865,257,16.0312
15.16467992,56.865,279,16.7033
15.20814568,56.865,321,17.9165
15.25161144,56.865,299,17.2916
15.2950772,56.865,273,16.5227
15.33854296,56.865,282,16.7929
15.38200872,56.865,286,16.9115
15.42547448,56.865,285,16.8819
15.46894024,56.865,319,17.8606
15.512406,56.865,300,17.3205
15.55587176,56.865,277,16.6433
15.59933752,56.865,298,17.2627
15.64280328,56.865,288,16.9706
15.68626904,56.865,291,17.0587
15.7297348,56.865,249,15.7797
15.77320056,56.865,290,17.0294
15.81666632,56.865,259,16.0935
15.86013208,56.865,279,16.7033
15.90359784,56.865,294,17.1464
15.9470636,56.865,309,17.5784
15.99052936,56.865,282,16.7929
16.03399512,56.865,303,17.4069
16.07746088,56.865,279,16.7033
16.12092664,56.865,296,17.2047
16.1643924,56.865,292,17.088
16.20785816,56.865,280,16.7332
16.25132392,56.865,291,17.0587
16.29478968,56.865,277,16.6433
16.33825544,56.865,274,16.5529
16.3817212,56.865,257,16.0312
16.42518696,56.865,296,17.2047
16.46865272,56.865,295,17.1756
16.51211848,56.865,266,16.3095
16.55558424,56.865,303,17.4069
16.59905,56.865,299,17.2916
16.64251576,56.865,266,16.3095
16.68598152,56.865,283,16.8226
16.72944728,56.865,279,16.7033
16.77291304,56.865,282,16.7929
16.8163788,56.865,260,16.1245
16.85984456,56.865,314,17.72
16.90331032,56.865,291,17.0587
16.94677608,56.865,301,17.3494
16.99024184,56.865,282,16.7929
17.0337076,56.865,295,17.1756
17.07717336,56.865,287,16.9411
17.12063912,56.865,289,17
17.16410488,56.865,284,16.8523
17.20757064,56.865,305,17.4642
17.2510364,56.865,287,16.9411
17.29450216,56.865,255,15.9687
17.33796792,56.865,261,16.1555
17.38143368,56.865,307,17.5214
17.42489944,56.865,286,16.9115
17.4683652,56.865,314,17.72
17.51183096,56.865,335,18.303
17.55529672,56.865,306,17.4929
17.59876248,56.865,313,17.6918
17.64222824,56.865,282,16.7929
17.685694,56.865,281,16.7631
17.72915976,56.865,264,16.2481
17.77262552,56.865,286,16.9115
17.81609128,56.865,338,18.3848
17.85955704,56.865,269,16.4012
17.9030228,56.865,295,17.1756
17.94648856,56.865,281,16.7631
17.98995432,56.865,331,18.1934
18.03342008,56.865,265,16.2788
18.07688584,56.865,322,17.9444
18.1203516,56.865,305,17.4642
18.16381736,56.865,343,18.5203
18.20728312,56.865,295,17.1756
18.25074888,56.865,312,17.6635
18.29421464,56.865,294,17.1464
18.3376804,56.865,299,17.2916
18.38114616,56.865,268,16.3707
18.42461192,56.865,326,18.0555
18.46807768,56.865,264,16.2481
18.51154344,56.865,252,15.8745
18.5550092,56.865,331,18.1934
18.59847496,56.865,275,16.5831
18.64194072,56.865,297,17.2337
18.68540648,56.865,292,17.088
18.72887224,56.865,310,17.6068
18.772338,56.865,327,18.0831
18.81580376,56.865,284,16.8523
18.85926952,56.865,287,16.9411
18.90273528,56.865,312,17.6635
18.94620104,56.865,282,16.7929
18.9896668,56.865,312,17.6635
19.03313256,56.865,312,17.6635
19.07659832,56.865,282,16.7929
19.12006408,56.865,280,16.7332
19.16352984,56.865,313,17.6918
19.2069956,56.865,329,18.1384
19.25046136,56.865,298,17.2627
19.29392712,56.865,294,17.1464
19.33739288,56.865,333,18.2483
19.38085864,56.865,309,17.5784
19.4243244,56.865,270,16.4317
19.46779016,56.865,322,17.9444
19.51125592,56.865,323,17.9722
19.55472168,56.865,306,17.4929
19.59818744,56.865,354,18.8149
19.6416532,56.865,327,18.0831
19.68511896,56.865,360,18.9737
19.72858472,56.865,366,19.1311
19.77205048,56.865,320,17.8885
19.81551624,56.865,365,19.105
19.858982,56.865,412,20.2978
19.90244776,56.865,461,21.4709
19.94591352,56.865,529,23
19.98937928,56.865,758,27.5318
20.03284504,56.865,1176,34.2929
20.0763108,56.865,1758,41.9285
20.11977656,56.865,1928,43.909
20.16324232,56.865,1120,33.4664
20.20670808,56.865,594,24.3721
20.25017384,56.865,453,21.2838
20.2936396,56.865,376,19.3907
20.33710536,56.865,395,19.8746
20.38057112,56.865,339,18.412
20.42403688,56.865,355,18.8414
20.46750264,56.865,294,17.1464
20.5109684,56.865,322,17.9444
20.55443416,56.865,360,18.9737
20.59789992,56.865,339,18.412
20.64136568,56.865,321,17.9165
20.68483144,56.865,331,18.1934
20.7282972,56.865,358,18.9209
20.77176296,56.865,360,18.9737
20.81522872,56.865,357,18.8944
20.85869448,56.865,350,18.7083
20.90216024,56.865,338,18.3848
20.945626,56.865,305,17.4642
20.98909176,56.865,313,17.6918
21.03255752,56.865,313,17.6918
21.07602328,56.865,327,18.0831
21.11948904,56.865,328,18.1108
21.1629548,56.865,358,18.9209
21.20642056,56.865,362,19.0263
21.24988632,56.865,334,18.2757
21.29335208,56.865,340,18.4391
21.33681784,56.865,364,19.0788
21.3802836,56.865,373,19.3132
21.42374936,56.865,381,19.5192
21.46721512,56.865,343,18.5203
21.51068088,56.865,386,19.6469
21.55414664,56.865,401,20.025
21.5976124,56.865,350,18.7083
21.64107816,56.865,401,20.025
21.68454392,56.865,359,18.9473
21.72800968,56.865,327,18.0831
21.77147544,56.865,372,19.2873
21.8149412,56.865,397,19.9249
21.85840696,56.865,345,18.5742
21.90187272,56.865,343,18.5203
21.94533848,56.865,328,18.1108
21.98880424,56.865,350,18.7083
22.03227,56.865,345,18.5742
22.07573576,56.865,356,18.868
22.11920152,56.865,367,19.1572
22.16266728,56.865,364,19.0788
22.20613304,56.865,397,19.9249
22.2495988,56.865,366,19.1311
22.29306456,56.865,370,19.2354
22.33653032,56.865,343,18.5203
22.37999608,56.865,392,19.799
22.42346184,56.865,352,18.7617
22.4669276,56.865,385,19.6214
22.51039336,56.865,413,20.3224
22.55385912,56.865,361,19
22.59732488,56.865,327,18.0831
22.64079064,56.865,360,18.9737
22.6842564,56.865,390,19.7484
22.72772216,56.865,364,19.0788
22.77118792,56.865,378,19.4422
22.81465368,56.865,375,19.3649
22.85811944,56.865,362,19.0263
22.9015852,56.865,347,18.6279
22.94505096,56.865,337,18.3576
22.98851672,56.865,363,19.0526
23.03198248,56.865,385,19.6214
23.07544824,56.865,379,19.4679
23.118914,56.865,370,19.2354
23.16237976,56.865,363,19.0526
23.20584552,56.865,390,19.7484
23.24931128,56.865,358,18.9209
23.29277704,56.865,431,20.7605
23.3362428,56.865,458,21.4009
23.37970856,56.865,491,22.1585
23.42317432,56.865,468,21.6333
23.46664008,56.865,425,20.6155
23.51010584,56.865,373,19.3132
23.5535716,56.865,367,19.1572
23.59703736,56.865,366,19.1311
23.64050312,56.865,370,19.2354
23.68396888,56.865,353,18.7883
23.72743464,56.865,377,19.4165
23.7709004,56.865,366,19.1311
23.81436616,56.865,442,21.0238
23.85783192,56.865,367,19.1572
23.90129768,56.865,376,19.3907
23.94476344,56.865,394,19.8494
23.9882292,56.865,363,19.0526
24.03169496,56.865,348,18.6548
24.07516072,56.865,346,18.6011
24.11862648,56.865,370,19.2354
24.16209224,56.865,386,19.6469
24.205558,56.865,375,19.3649
24.24902376,56.865,422,20.5426
24.29248952,56.865,393,19.8242
24.33595528,56.865,347,18.6279
24.37942104,56.865,419,20.4695
24.4228868,56.865,432,20.7846
24.46635256,56.865,442,21.0238
24.50981832,56.865,598,24.454
24.55328408,56.865,684,26.1534
24.59674984,56.865,961,31
24.6402156,56.865,941,30.6757
24.68368136,56.865,787,28.0535
24.72714712,56.865,574,23.9583
24.77061288,56.865,466,21.587
24.81407864,56.865,415,20.3715
24.8575444,56.865,443,21.0476
24.90101016,56.865,380,19.4936
24.94447592,56.865,363,19.0526
24.98794168,56.865,381,19.5192
25.03140744,56.865,368,19.1833
25.0748732,56.865,366,19.1311
25.11833896,56.865,421,20.5183
25.16180472,56.865,400,20
25.20527048,56.865,398,19.9499
25.24873624,56.865,371,19.2614
25.292202,56.865,386,19.6469
25.33566776,56.865,387,19.6723
25.37913352,56.865,356,18.868
25.42259928,56.865,425,20.6155
25.46606504,56.865,385,19.6214
25.5095308,56.865,387,19.6723
25.55299656,56.865,371,19.2614
25.59646232,56.865,371,19.2614
25.63992808,56.865,398,19.9499
25.68339384,56.865,362,19.0263
25.7268596,56.865,388,19.6977
25.77032536,56.865,403,20.0749
25.81379112,56.865,364,19.0788
25.85725688,56.865,370,19.2354
25.90072264,56.865,399,19.975
25.9441884,56.865,392,19.799
25.98765416,56.865,388,19.6977
26.03111992,56.865,383,19.5704
26.07458568,56.865,361,19
26.11805144,56.865,382,19.5448
26.1615172,56.865,401,20.025
26.20498296,56.865,373,19.3132
26.24844872,56.865,424,20.5913
26.29191448,56.865,349,18.6815
26.33538024,56.865,403,20.0749
26.378846,56.865,379,19.4679
26.42231176,56.865,380,19.4936
26.46577752,56.865,359,18.9473
26.50924328,56.865,354,18.8149
26.55270904,56.865,374,19.3391
26.5961748,56.865,395,19.8746
26.63964056,56.865,372,19.2873
26.68310632,56.865,380,19.4936
26.72657208,56.865,400,20
26.77003784,56.865,363,19.0526
26.8135036,56.865,396,19.8997
26.85696936,56.865,436,20.8806
26.90043512,56.865,405,20.1246
26.94390088,56.865,432,20.7846
26.98736664,56.865,408,20.199
27.0308324,56.865,431,20.7605
27.07429816,56.865,470,21.6795
27.11776392,56.865,546,23.3666
27.16122968,56.865,480,21.9089
27.20469544,56.865,499,22.3383
27.2481612,56.865,513,22.6495
27.29162696,56.865,539,23.2164
27.33509272,56.865,514,22.6716
27.37855848,56.865,481,21.9317
27.42202424,56.865,406,20.1494
27.46549,56.865,369,19.2094
27.50895576,56.865,379,19.4679
27.55242152,56.865,360,18.9737
27.59588728,56.865,399,19.975
27.63935304,56.865,399,19.975
27.6828188,56.865,385,19.6214
27.72628456,56.865,416,20.3961
27.76975032,56.865,402,20.0499
27.81321608,56.865,378,19.4422
27.85668184,56.865,377,19.4165
27.9001476,56.865,368,19.1833
27.94361336,56.865,387,19.6723
27.98707912,56.865,383,19.5704
28.03054488,56.865,424,20.5913
28.07401064,56.865,404,20.0998
28.1174764,56.865,431,20.7605
28.16094216,56.865,437,20.9045
28.20440792,56.865,427,20.664
28.24787368,56.865,489,22.1133
28.29133944,56.865,551,23.4734
28.3348052,56.865,745,27.2947
28.37827096,56.865,922,30.3645
28.42173672,56.865,1439,37.9342
28.46520248,56.865,1681,41
28.50866824,56.865,1254,35.4119
28.552134,56.865,935,30.5778
28.59559976,56.865,582,24.1247
28.63906552,56.865,445,21.095
28.68253128,56.865,435,20.8567
28.72599704,56.865,398,19.9499
28.7694628,56.865,379,19.4679
28.81292856,56.865,366,19.1311
28.85639432,56.865,353,18.7883
28.89986008,56.865,377,19.4165
28.94332584,56.865,349,18.6815
28.9867916,56.865,343,18.5203
29.03025736,56.865,361,19
29.07372312,56.865,366,19.1311
29.11718888,56.865,378,19.4422
29.16065464,56.865,361,19
29.2041204,56.865,405,20.1246
29.24758616,56.865,354,18.8149
29.29105192,56.865,357,18.8944
29.33451768,56.865,330,18.1659
29.37798344,56.865,349,18.6815
29.4214492,56.865,327,18.0831
29.46491496,56.865,333,18.2483
29.50838072,56.865,342,18.4932
29.55184648,56.865,336,18.3303
29.59531224,56.865,359,18.9473
29.638778,56.865,344,18.5472
29.68224376,56.865,350,18.7083
29.72570952,56.865,362,19.0263
29.76917528,56.865,330,18.1659
29.81264104,56.865,362,19.0263
29.8561068,56.865,336,18.3303
29.89957256,56.865,341,18.4662
29.94303832,56.865,354,18.8149
29.98650408,56.865,312,17.6635
30.02996984,56.865,367,19.1572
30.0734356,56.865,353,18.7883
30.11690136,56.865,355,18.8414
30.16036712,56.865,385,19.6214
30.20383288,56.865,377,19.4165
30.24729864,56.865,420,20.4939
30.2907644,56.865,435,20.8567
30.33423016,56.865,486,22.0454
30.37769592,56.865,503,22.4277
30.42116168,56.865,462,21.4942
30.46462744,56.865,473,21.7486
30.5080932,56.865,485,22.0227
30.55155896,56.865,430,20.7364
30.59502472,56.865,440,20.9762
30.63849048,56.865,446,21.1187
30.68195624,56.865,405,20.1246
30.725422,56.865,387,19.6723
30.76888776,56.865,372,19.2873
30.81235352,56.865,357,18.8944
30.85581928,56.865,404,20.0998
30.89928504,56.865,394,19.8494
30.9427508,56.865,336,18.3303
30.98621656,56.865,353,18.7883
31.02968232,56.865,389,19.7231
31.07314808,56.865,330,18.1659
31.11661384,56.865,371,19.2614
31.1600796,56.865,343,18.5203
31.20354536,56.865,328,18.1108
31.24701112,56.865,302,17.3781
31.29047688,56.865,372,19.2873
31.33394264,56.865,377,19.4165
31.3774084,56.865,352,18.7617
31.42087416,56.865,358,18.9209
31.46433992,56.865,357,18.8944
31.50780568,56.865,357,18.8944
31.55127144,56.865,381,19.5192
31.5947372,56.865,391,19.7737
31.63820296,56.865,336,18.3303
31.68166872,56.865,387,19.6723
31.72513448,56.865,485,22.0227
31.76860024,56.865,686,26.1916
31.812066,56.865,968,31.1127
31.85553176,56.865,1578,39.724
31.89899752,56.865,1797,42.391
31.94246328,56.865,1547,39.3319
31.98592904,56.865,1098,33.1361
32.0293948,56.865,671,25.9037
32.07286056,56.865,446,21.1187
32.11632632,56.865,375,19.3649
32.15979208,56.865,366,19.1311
32.20325784,56.865,344,18.5472
32.2467236,56.865,397,19.9249
32.29018936,56.865,383,19.5704
32.33365512,56.865,365,19.105
32.37712088,56.865,377,19.4165
32.42058664,56.865,329,18.1384
32.4640524,56.865,330,18.1659
32.50751816,56.865,312,17.6635
32.55098392,56.865,345,18.5742
32.59444968,56.865,321,17.9165
32.63791544,56.865,286,16.9115
32.6813812,56.865,317,17.8045
32.72484696,56.865,319,17.8606
32.76831272,56.865,319,17.8606
32.81177848,56.865,328,18.1108
32.85524424,56.865,290,17.0294
32.89871,56.865,291,17.0587
32.94217576,56.865,294,17.1464
32.98564152,56.865,335,18.303
33.02910728,56.865,317,17.8045
33.07257304,56.865,288,16.9706
33.1160388,56.865,303,17.4069
33.15950456,56.865,297,17.2337
33.20297032,56.865,302,17.3781
33.24643608,56.865,330,18.1659
33.28990184,56.865,286,16.9115
33.3333676,56.865,341,18.4662
33.37683336,56.865,326,18.0555
33.42029912,56.865,285,16.8819
33.46376488,56.865,282,16.7929
33.50723064,56.865,298,17.2627
33.5506964,56.865,327,18.0831
33.59416216,56.865,324,18
33.63762792,56.865,329,18.1384
33.68109368,56.865,319,17.8606
33.72455944,56.865,309,17.5784
33.7680252,56.865,318,17.8326
33.81149096,56.865,291,17.0587
33.85495672,56.865,305,17.4642
33.89842248,56.865,315,17.7482
33.94188824,56.865,300,17.3205
33.985354,56.865,300,17.3205
34.02881976,56.865,297,17.2337
34.07228552,56.865,314,17.72
34.11575128,56.865,331,18.1934
34.15921704,56.865,303,17.4069
34.2026828,56.865,277,16.6433
34.24614856,56.865,315,17.7482
34.28961432,56.865,286,16.9115
34.33308008,56.865,269,16.4012
34.37654584,56.865,308,17.5499
34.4200116,56.865,296,17.2047
34.46347736,56.865,292,17.088
34.50694312,56.865,289,17
34.55040888,56.865,277,16.6433
34.59387464,56.865,279,16.7033
34.6373404,56.865,279,16.7033
34.68080616,56.865,270,16.4317
34.72427192,56.865,287,16.9411
34.76773768,56.865,290,17.0294
34.81120344,56.865,347,18.6279
34.8546692,56.865,372,19.2873
34.89813496,56.865,393,19.8242
34.94160072,56.865,656,25.6125
34.98506648,56.865,877,29.6142
35.02853224,56.865,1057,32.5115
35.071998,56.865,1098,33.1361
35.11546376,56.865,913,30.2159
35.15892952,56.865,642,25.3377
35.20239528,56.865,476,21.8174
35.24586104,56.865,373,19.3132
35.2893268,56.865,349,18.6815
35.33279256,56.865,353,18.7883
35.37625832,56.865,358,18.9209
35.41972408,56.865,332,18.2209
35.46318984,56.865,332,18.2209
35.5066556,56.865,307,17.5214
35.55012136,56.865,297,17.2337
35.59358712,56.865,308,17.5499
35.63705288,56.865,287,16.9411
35.68051864,56.865,245,15.6525
35.7239844,56.865,274,16.5529
35.76745016,56.865,287,16.9411
35.81091592,56.865,296,17.2047
35.85438168,56.865,277,16.6433
35.89784744,56.865,248,15.748
35.9413132,56.865,268,16.3707
35.98477896,56.865,272,16.4924
36.02824472,56.865,242,15.5563
36.07171048,56.865,265,16.2788
36.11517624,56.865,252,15.8745
36.158642,56.865,273,16.5227
36.20210776,56.865,285,16.8819
36.24557352,56.865,275,16.5831
36.28903928,56.865,247,15.7162
36.33250504,56.865,266,16.3095
36.3759708,56.865,250,15.8114
36.41943656,56.865,276,16.6132
36.46290232,56.865,257,16.0312
36.50636808,56.865,225,15
36.54983384,56.865,273,16.5227
36.5932996,56.865,274,16.5529
36.63676536,56.865,254,15.9374
36.68023112,56.865,289,17
36.72369688,56.865,249,15.7797
36.76716264,56.865,258,16.0624
36.8106284,56.865,277,16.6433
36.85409416,56.865,285,16.8819
36.89755992,56.865,285,16.8819
36.94102568,56.865,248,15.748
36.98449144,56.865,271,16.4621
37.0279572,56.865,260,16.1245
37.07142296,56.865,238,15.4272
37.11488872,56.865,265,16.2788
37.15835448,56.865,280,16.7332
37.20182024,56.865,250,15.8114
37.245286,56.865,260,16.1245
37.28875176,56.865,233,15.2643
37.33221752,56.865,230,15.1658
37.37568328,56.865,250,15.8114
37.41914904,56.865,262,16.1864
37.4626148,56.865,272,16.4924
37.50608056,56.865,248,15.748
37.54954632,56.865,242,15.5563
37.59301208,56.865,260,16.1245
37.63647784,56.865,261,16.1555
37.6799436,56.865,216,14.6969
37.72340936,56.865,258,16.0624
37.76687512,56.865,259,16.0935
37.81034088,56.865,255,15.9687
37.85380664,56.865,267,16.3401
37.8972724,56.865,230,15.1658
37.94073816,56.865,291,17.0587
37.98420392,56.865,258,16.0624
38.02766968,56.865,238,15.4272
38.07113544,56.865,227,15.0665
38.1146012,56.865,263,16.2173
38.15806696,56.865,261,16.1555
38.20153272,56.865,232,15.2315
38.24499848,56.865,242,15.5563
38.28846424,56.865,237,15.3948
38.33193,56.865,229,15.1327
38.37539576,56.865,229,15.1327
38.41886152,56.865,233,15.2643
38.46232728,56.865,269,16.4012
38.50579304,56.865,255,15.9687
38.5492588,56.865,266,16.3095
38.59272456,56.865,269,16.4012
38.63619032,56.865,299,17.2916
38.67965608,56.865,283,16.8226
38.72312184,56.865,296,17.2047
38.7665876,56.865,275,16.5831
38.81005336,56.865,249,15.7797
38.85351912,56.865,263,16.2173
38.89698488,56.865,238,15.4272
38.94045064,56.865,219,14.7986
38.9839164,56.865,238,15.4272
39.02738216,56.865,218,14.7648
39.07084792,56.865,222,14.8997
39.11431368,56.865,251,15.843
39.15777944,56.865,230,15.1658
39.2012452,56.865,255,15.9687
39.24471096,56.865,232,15.2315
39.28817672,56.865,246,15.6844
39.33164248,56.865,266,16.3095
39.37510824,56.865,242,15.5563
39.418574,56.865,227,15.0665
39.46203976,56.865,230,15.1658
39.50550552,56.865,246,15.6844
39.54897128,56.865,290,17.0294
39.59243704,56.865,227,15.0665
39.6359028,56.865,247,15.7162
39.67936856,56.865,216,14.6969
39.72283432,56.865,221,14.8661
39.76630008,56.865,264,16.2481
39.80976584,56.865,249,15.7797
39.8532316,56.865,240,15.4919
39.89669736,56.865,213,14.5945
39.94016312,56.865,250,15.8114
39.98362888,56.865,258,16.0624
40.02709464,56.865,248,15.748
40.0705604,56.865,243,15.5885
40.11402616,56.865,303,17.4069
40.15749192,56.865,277,16.6433
40.20095768,56.865,263,16.2173
40.24442344,56.865,254,15.9374
40.2878892,56.865,279,16.7033
40.33135496,56.865,272,16.4924
40.37482072,56.865,372,19.2873
40.41828648,56.865,370,19.2354
40.46175224,56.865,490,22.1359
40.505218,56.865,787,28.0535
40.54868376,56.865,1369,37
40.59214952,56.865,2024,44.9889
40.63561528,56.865,2336,48.3322
40.67908104,56.865,2477,49.7695
40.7225468,56.865,2004,44.7661
40.76601256,56.865,1398,37.3898
40.80947832,56.865,900,30
40.85294408,56.865,587,24.2281
40.89640984,56.865,437,20.9045
40.9398756,56.865,337,18.3576
40.98334136,56.865,326,18.0555
41.02680712,56.865,280,16.7332
41.07027288,56.865,289,17
41.11373864,56.865,282,16.7929
41.1572044,56.865,264,16.2481
41.20067016,56.865,264,16.2481
41.24413592,56.865,247,15.7162
41.28760168,56.865,266,16.3095
41.33106744,56.865,253,15.906
41.3745332,56.865,259,16.0935
41.41799896,56.865,279,16.7033
41.46146472,56.865,267,16.3401
41.50493048,56.865,266,16.3095
41.54839624,56.865,247,15.7162
41.591862,56.865,253,15.906
41.63532776,56.865,249,15.7797
41.67879352,56.865,256,16
41.72225928,56.865,229,15.1327
41.76572504,56.865,229,15.1327
41.8091908,56.865,257,16.0312
41.85265656,56.865,246,15.6844
41.89612232,56.865,196,14
41.93958808,56.865,252,15.8745
41.98305384,56.865,231,15.1987
42.0265196,56.865,240,15.4919
42.06998536,56.865,235,15.3297
42.11345112,56.865,258,16.0624
42.15691688,56.865,235,15.3297
42.20038264,56.865,252,15.8745
42.2438484,56.865,256,16
42.28731416,56.865,249,15.7797
42.33077992,56.865,238,15.4272
42.37424568,56.865,233,15.2643
42.41771144,56.865,235,15.3297
42.4611772,56.865,238,15.4272
42.50464296,56.865,256,16
42.54810872,56.865,241,15.5242
42.59157448,56.865,232,15.2315
42.63504024,56.865,229,15.1327
42.678506,56.865,244,15.6205
42.72197176,56.865,269,16.4012
42.76543752,56.865,241,15.5242
42.80890328,56.865,260,16.1245
42.85236904,56.865,256,16
42.8958348,56.865,238,15.4272
42.93930056,56.865,261,16.1555
42.98276632,56.865,259,16.0935
43.02623208,56.865,282,16.7929
43.06969784,56.865,419,20.4695
43.1131636,56.865,563,23.7276
43.15662936,56.865,727,26.9629
43.20009512,56.865,748,27.3496
43.24356088,56.865,664,25.7682
43.28702664,56.865,651,25.5147
43.3304924,56.865,477,21.8403
43.37395816,56.865,364,19.0788
43.41742392,56.865,366,19.1311
43.46088968,56.865,288,16.9706
43.50435544,56.865,255,15.9687
43.5478212,56.865,242,15.5563
43.59128696,56.865,225,15
43.63475272,56.865,246,15.6844
43.67821848,56.865,233,15.2643
43.72168424,56.865,245,15.6525
43.76515,56.865,236,15.3623
43.80861576,56.865,229,15.1327
43.85208152,56.865,257,16.0312
43.89554728,56.865,231,15.1987
43.93901304,56.865,212,14.5602
43.9824788,56.865,233,15.2643
44.02594456,56.865,234,15.2971
44.06941032,56.865,225,15
44.11287608,56.865,210,14.4914
44.15634184,56.865,241,15.5242
44.1998076,56.865,244,15.6205
44.24327336,56.865,223,14.9332
44.28673912,56.865,216,14.6969
44.33020488,56.865,219,14.7986
44.37367064,56.865,215,14.6629
44.4171364,56.865,225,15
44.46060216,56.865,211,14.5258
44.50406792,56.865,234,15.2971
44.54753368,56.865,232,15.2315
44.59099944,56.865,219,14.7986
44.6344652,56.865,210,14.4914
44.67793096,56.865,219,14.7986
44.72139672,56.865,216,14.6969
44.76486248,56.865,230,15.1658
44.80832824,56.865,196,14
44.851794,56.865,226,15.0333
44.89525976,56.865,236,15.3623
44.93872552,56.865,232,15.2315
44.98219128,56.865,260,16.1245
45.02565704,56.865,231,15.1987
45.0691228,56.865,198,14.0712
45.11258856,56.865,206,14.3527
45.15605432,56.865,240,15.4919
45.19952008,56.865,241,15.5242
45.24298584,56.865,254,15.9374
45.2864516,56.865,206,14.3527
45.32991736,56.865,230,15.1658
45.37338312,56.865,266,16.3095
45.41684888,56.865,245,15.6525
45.46031464,56.865,222,14.8997
45.5037804,56.865,226,15.0333
45.54724616,56.865,251,15.843
45.59071192,56.865,254,15.9374
45.63417768,56.865,237,15.3948
45.67764344,56.865,239,15.4596
45.7211092,56.865,246,15.6844
45.76457496,56.865,237,15.3948
45.80804072,56.865,229,15.1327
45.85150648,56.865,235,15.3297
45.89497224,56.865,245,15.6525
45.938438,56.865,213,14.5945
45.98190376,56.865,194,13.9284
46.02536952,56.865,225,15
46.06883528,56.865,245,15.6525
46.11230104,56.865,228,15.0997
46.1557668,56.865,212,14.5602
46.19923256,56.865,241,15.5242
46.24269832,56.865,200,14.1421
46.28616408,56.865,213,14.5945
46.32962984,56.865,207,14.3875
46.3730956,56.865,218,14.7648
46.41656136,56.865,205,14.3178
46.46002712,56.865,196,14
46.50349288,56.865,207,14.3875
46.54695864,56.865,192,13.8564
46.5904244,56.865,208,14.4222
46.63389016,56.865,170,13.0384
46.67735592,56.865,180,13.4164
46.72082168,56.865,199,14.1067
46.76428744,56.865,195,13.9642
46.8077532,56.865,208,14.4222
46.85121896,56.865,200,14.1421
46.89468472,56.865,209,14.4568
46.93815048,56.865,199,14.1067
46.98161624,56.865,213,14.5945
47.025082,56.865,218,14.7648
47.06854776,56.865,206,14.3527
47.11201352,56.865,209,14.4568
47.15547928,56.865,205,14.3178
47.19894504,56.865,182,13.4907
47.2424108,56.865,191,13.8203
47.28587656,56.865,190,13.784
47.32934232,56.865,211,14.5258
47.37280808,56.865,187,13.6748
47.41627384,56.865,195,13.9642
47.4597396,56.865,198,14.0712
47.50320536,56.865,204,14.2829
47.54667112,56.865,191,13.8203
47.59013688,56.865,205,14.3178
47.63360264,56.865,213,14.5945
47.6770684,56.865,219,14.7986
47.72053416,56.865,203,14.2478
47.76399992,56.865,189,13.7477
47.80746568,56.865,180,13.4164
47.85093144,56.865,189,13.7477
47.8943972,56.865,205,14.3178
47.93786296,56.865,223,14.9332
47.98132872,56.865,198,14.0712
48.02479448,56.865,200,14.1421
48.06826024,56.865,197,14.0357
48.111726,56.865,189,13.7477
48.15519176,56.865,212,14.5602
48.19865752,56.865,216,14.6969
48.24212328,56.865,189,13.7477
48.28558904,56.865,195,13.9642
48.3290548,56.865,193,13.8924
48.37252056,56.865,190,13.784
48.41598632,56.865,227,15.0665
48.45945208,56.865,184,13.5647
48.50291784,56.865,192,13.8564
48.5463836,56.865,194,13.9284
48.58984936,56.865,176,13.2665
48.63331512,56.865,194,13.9284
48.67678088,56.865,201,14.1774
48.72024664,56.865,168,12.9615
48.7637124,56.865,201,14.1774
48.80717816,56.865,193,13.8924
48.85064392,56.865,184,13.5647
48.89410968,56.865,194,13.9284
48.93757544,56.865,186,13.6382
48.9810412,56.865,197,14.0357
49.02450696,56.865,188,13.7113
49.06797272,56.865,205,14.3178
49.11143848,56.865,203,14.2478
49.15490424,56.865,203,14.2478
49.19837,56.865,189,13.7477
49.24183576,56.865,187,13.6748
49.28530152,56.865,195,13.9642
49.32876728,56.865,209,14.4568
49.37223304,56.865,194,13.9284
49.4156988,56.865,191,13.8203
49.45916456,56.865,194,13.9284
49.50263032,56.865,205,14.3178
49.54609608,56.865,228,15.0997
49.58956184,56.865,192,13.8564
49.6330276,56.865,186,13.6382
49.67649336,56.865,187,13.6748
49.71995912,56.865,183,13.5277
49.76342488,56.865,180,13.4164
49.80689064,56.865,166,12.8841
49.8503564,56.865,169,13
49.89382216,56.865,185,13.6015
49.93728792,56.865,182,13.4907
49.98075368,56.865,190,13.784
50.02421944,56.865,192,13.8564
50.0676852,56.865,232,15.2315
50.11115096,56.865,240,15.4919
50.15461672,56.865,276,16.6132
50.19808248,56.865,290,17.0294
50.24154824,56.865,365,19.105
50.285014,56.865,313,17.6918
50.32847976,56.865,301,17.3494
50.37194552,56.865,319,17.8606
50.41541128,56.865,295,17.1756
50.45887704,56.865,256,16
50.5023428,56.865,264,16.2481
50.54580856,56.865,210,14.4914
50.58927432,56.865,228,15.0997
50.63274008,56.865,245,15.6525
50.67620584,56.865,204,14.2829
50.7196716,56.865,225,15
50.76313736,56.865,223,14.9332
50.80660312,56.865,236,15.3623
50.85006888,56.865,236,15.3623
50.89353464,56.865,239,15.4596
50.9370004,56.865,214,14.6287
50.98046616,56.865,204,14.2829
51.02393192,56.865,206,14.3527
51.06739768,56.865,217,14.7309
51.11086344,56.865,234,15.2971
51.1543292,56.865,188,13.7113
51.19779496,56.865,193,13.8924
51.24126072,56.865,195,13.9642
51.28472648,56.865,189,13.7477
51.32819224,56.865,175,13.2288
51.371658,56.865,189,13.7477
51.41512376,56.865,182,13.4907
51.45858952,56.865,172,13.1149
51.50205528,56.865,172,13.1149
51.54552104,56.865,180,13.4164
51.5889868,56.865,150,12.2474
51.63245256,56.865,161,12.6886
51.67591832,56.865,164,12.8062
51.71938408,56.865,164,12.8062
51.76284984,56.865,207,14.3875
51.8063156,56.865,187,13.6748
51.84978136,56.865,193,13.8924
51.89324712,56.865,178,13.3417
51.93671288,56.865,175,13.2288
51.98017864,56.865,198,14.0712
52.0236444,56.865,165,12.8452
52.06711016,56.865,171,13.0767
52.11057592,56.865,191,13.8203
52.15404168,56.865,193,13.8924
52.19750744,56.865,200,14.1421
52.2409732,56.865,211,14.5258
52.28443896,56.865,184,13.5647
52.32790472,56.865,186,13.6382
52.37137048,56.865,249,15.7797
52.41483624,56.865,275,16.5831
52.458302,56.865,283,16.8226
52.50176776,56.865,255,15.9687
52.54523352,56.865,300,17.3205
52.58869928,56.865,251,15.843
52.63216504,56.865,227,15.0665
52.6756308,56.865,231,15.1987
52.71909656,56.865,176,13.2665
52.76256232,56.865,192,13.8564
52.80602808,56.865,171,13.0767
52.84949384,56.865,201,14.1774
52.8929596,56.865,174,13.1909
52.93642536,56.865,166,12.8841
52.97989112,56.865,193,13.8924
53.02335688,56.865,171,13.0767
53.06682264,56.865,185,13.6015
53.1102884,56.865,224,14.9666
53.15375416,56.865,179,13.3791
53.19721992,56.865,163,12.7671
53.24068568,56.865,186,13.6382
53.28415144,56.865,179,13.3791
53.3276172,56.865,160,12.6491
53.37108296,56.865,161,12.6886
53.41454872,56.865,167,12.9228
53.45801448,56.865,167,12.9228
53.50148024,56.865,176,13.2665
53.544946,56.865,187,13.6748
53.58841176,56.865,180,13.4164
53.63187752,56.865,168,12.9615
53.67534328,56.865,183,13.5277
53.71880904,56.865,183,13.5277
53.7622748,56.865,188,13.7113
53.80574056,56.865,189,13.7477
53.84920632,56.865,205,14.3178
53.89267208,56.865,173,13.1529
53.93613784,56.865,169,13
53.9796036,56.865,169,13
54.02306936,56.865,141,11.8743
54.06653512,56.865,176,13.2665
54.11000088,56.865,201,14.1774
54.15346664,56.865,166,12.8841
54.1969324,56.865,215,14.6629
54.24039816,56.865,183,13.5277
54.28386392,56.865,179,13.3791
54.32732968,56.865,163,12.7671
54.37079544,56.865,164,12.8062
54.4142612,56.865,201,14.1774
54.45772696,56.865,193,13.8924
54.50119272,56.865,198,14.0712
54.54465848,56.865,214,14.6287
54.58812424,56.865,208,14.4222
54.63159,56.865,179,13.3791
54.67505576,56.865,216,14.6969
54.71852152,56.865,230,15.1658
54.76198728,56.865,187,13.6748
54.80545304,56.865,213,14.5945
54.8489188,56.865,191,13.8203
54.89238456,56.865,177,13.3041
54.93585032,56.865,188,13.7113
54.97931608,56.865,192,13.8564
55.02278184,56.865,201,14.1774
55.0662476,56.865,151,12.2882
55.10971336,56.865,147,12.1244
55.15317912,56.865,164,12.8062
55.19664488,56.865,184,13.5647
55.24011064,56.865,185,13.6015
55.2835764,56.865,172,13.1149
55.32704216,56.865,183,13.5277
55.37050792,56.865,178,13.3417
55.41397368,56.865,197,14.0357
55.45743944,56.865,162,12.7279
55.5009052,56.865,162,12.7279
55.54437096,56.865,164,12.8062
55.58783672,56.865,159,12.6095
55.63130248,56.865,176,13.2665
55.67476824,56.865,179,13.3791
55.718234,56.865,170,13.0384
55.76169976,56.865,166,12.8841
55.80516552,56.865,185,13.6015
55.84863128,56.865,177,13.3041
55.89209704,56.865,198,14.0712
55.9355628,56.865,173,13.1529
55.97902856,56.865,194,13.9284
56.02249432,56.865,185,13.6015
56.06596008,56.865,177,13.3041
56.10942584,56.865,182,13.4907
56.1528916,56.865,164,12.8062
56.19635736,56.865,193,13.8924
56.23982312,56.865,182,13.4907
56.28328888,56.865,167,12.9228
56.32675464,56.865,168,12.9615
56.3702204,56.865,164,12.8062
56.41368616,56.865,176,13.2665
56.45715192,56.865,179,13.3791
56.50061768,56.865,183,13.5277
56.54408344,56.865,170,13.0384
56.5875492,56.865,144,12
56.63101496,56.865,169,13
56.67448072,56.865,150,12.2474
56.71794648,56.865,174,13.1909
56.76141224,56.865,172,13.1149
56.804878,56.865,184,13.5647
56.84834376,56.865,198,14.0712
56.89180952,56.865,152,12.3288
56.93527528,56.865,151,12.2882
56.97874104,56.865,163,12.7671
57.0222068,56.865,165,12.8452
57.06567256,56.865,195,13.9642
57.10913832,56.865,167,12.9228
57.15260408,56.865,164,12.8062
57.19606984,56.865,182,13.4907
57.2395356,56.865,168,12.9615
57.28300136,56.865,187,13.6748
57.32646712,56.865,157,12.53
57.36993288,56.865,169,13
57.41339864,56.865,158,12.5698
57.4568644,56.865,173,13.1529
57.50033016,56.865,159,12.6095
57.54379592,56.865,184,13.5647
57.58726168,56.865,181,13.4536
57.63072744,56.865,181,13.4536
57.6741932,56.865,139,11.7898
57.71765896,56.865,181,13.4536
57.76112472,56.865,171,13.0767
57.80459048,56.865,165,12.8452
57.84805624,56.865,202,14.2127
57.891522,56.865,176,13.2665
57.93498776,56.865,162,12.7279
57.97845352,56.865,187,13.6748
58.02191928,56.865,166,12.8841
58.06538504,56.865,163,12.7671
58.1088508,56.865,161,12.6886
58.15231656,56.865,165,12.8452
58.19578232,56.865,169,13
58.23924808,56.865,154,12.4097
58.28271384,56.865,192,13.8564
58.3261796,56.865,183,13.5277
58.36964536,56.865,174,13.1909
58.41311112,56.865,191,13.8203
58.45657688,56.865,166,12.8841
58.50004264,56.865,157,12.53
58.5435084,56.865,188,13.7113
58.58697416,56.865,192,13.8564
58.63043992,56.865,170,13.0384
58.67390568,56.865,177,13.3041
58.71737144,56.865,165,12.8452
58.7608372,56.865,173,13.1529
58.80430296,56.865,177,13.3041
58.84776872,56.865,176,13.2665
58.89123448,56.865,167,12.9228
58.93470024,56.865,168,12.9615
58.978166,56.865,181,13.4536
59.02163176,56.865,186,13.6382
59.06509752,56.865,181,13.4536
59.10856328,56.865,156,12.49
59.15202904,56.865,188,13.7113
59.1954948,56.865,189,13.7477
59.23896056,56.865,177,13.3041
59.28242632,56.865,169,13
59.32589208,56.865,180,13.4164
59.36935784,56.865,202,14.2127
59.4128236,56.865,201,14.1774
59.45628936,56.865,171,13.0767
59.49975512,56.865,188,13.7113
59.54322088,56.865,160,12.6491
59.58668664,56.865,153,12.3693
59.6301524,56.865,201,14.1774
59.67361816,56.865,166,12.8841
59.71708392,56.865,181,13.4536
59.76054968,56.865,189,13.7477
59.80401544,56.865,177,13.3041
59.8474812,56.865,166,12.8841
59.89094696,56.865,170,13.0384
59.93441272,56.865,173,13.1529